Workbook

Sheet Cover
B3: GOLDBERG FAMILY OFFICE
B9: 17 Castlereagh Street
B16: Asset Summary — Tenancy Schedule
B18: As at 30 June 2026
B27: — | C27: Prepared by jake goldberg

Sheet Last Updated
A1: 17 CASTLEREAGH STREET, SYDNEY — TRACKER VERSION CONTROL
A2: Record each monthly update below. Update the 'Current Version' fields whenever Input Data is refreshed from the DJ Wear Tenancy Schedule.
B4: CURRENT TRACKER STATUS
B5: Property | D5: 17 Castlereagh Street, Sydney
B6: Current As At | D6: 46234
B7: Total NLA | D7: =SUM('Input Data'!F3:F27) -> 4704.5
B8: Occupancy | D8: =(SUM('Input Data'!F3:F27)-'Input Data'!F27)/SUM('Input Data'!F3:F27) -> 0.96592624
B9: WALE by NLA | D9: =IFERROR(SUMPRODUCT(('Input Data'!K3:K27>0)*'Input Data'!F3:F27*MAX(('Input Data'!H3:H27-TODAY())/365.25,0))/SUMIF('Input Data'!K3:K27,">0",'Input Data'!F3:F27),0) -> 0
B10: WALE by Income | D10: =IFERROR(SUMPRODUCT(('Input Data'!N3:N27>0)*'Input Data'!N3:N27*MAX(('Input Data'!H3:H27-TODAY())/365.25,0))/SUMIF('Input Data'!N3:N27,">0"),0) -> 0
B11: Gross Income PA | D11: =SUMIF('Input Data'!K3:K27,">0") -> 4907584.1
B12: Net Income PA | D12: =SUM('Input Data'!N3:N27) -> 4033664.6
B13: No. of Leases | D13: 23 active | 1 vacant | 1 owner-occupied
B14: Car Parks | D14: 2 garages, 1 tandem space each (74 bay licences to tenants)
B15: Last Updated By
B16: Next Update Due
B17: Notes / Changes
B19: UPDATE LOG — add a row each time you refresh the data
B20: Date Updated | C20: Updated By | D20: As At Date (Schedule) | E20: Occupancy | F20: WALE (NLA) | G20: Key Changes / Notes
B21: 46142 | D21: 30/04/2026 | E21: =(SUM('Input Data'!F3:F27)-'Input Data'!F27)/SUM('Input Data'!F3:F27) -> 0.96592624 | F21: =IFERROR(SUMPRODUCT(('Input Data'!K3:K27>0)*'Input Data'!F3:F27*MAX(('Input Data'!H3:H27-TODAY())/365.25,0))/SUMIF('Input Data'!K3:K27,">0",'Input Data'!F3:F27),0) -> 0 | G21: Initial setup — data loaded from DJ Wear Tenancy Schedule Apr 2026
B22: 46204 | C22: Jake | D22: 01/07/2026 | E22: =(SUM('Input Data'!F3:F27)-'Input Data'!F27)/SUM('Input Data'!F3:F27) -> 0.96592624 | F22: =IFERROR(SUMPRODUCT(('Input Data'!K3:K27>0)*'Input Data'!F3:F27*MAX(('Input Data'!H3:H27-TODAY())/365.25,0))/SUMIF('Input Data'!K3:K27,">0",'Input Data'!F3:F27),0) -> 0 | G22: Refreshed from DJ Wear Tenancy Schedule as at 1.7.2026: PU Prime, IPM Residential, Threat Defence, Satellite Office rent reviews applied; Aitken Investment Mgmt lease dates/PSM corrected; TJC#1 trading name updated to Balance Insolvency. Suite 101&2 (Blitzem) expires 30/6/2026 — will show vacant from next update.
B23: 46234 | C23: Jake | D23: 31/07/2026 | E23: =(SUM('Input Data'!F3:F27)-'Input Data'!F27)/SUM('Input Data'!F3:F27) -> 0.96592624 | F23: =IFERROR(SUMPRODUCT(('Input Data'!K3:K27>0)*'Input Data'!F3:F27*MAX(('Input Data'!H3:H27-TODAY())/365.25,0))/SUMIF('Input Data'!K3:K27,">0",'Input Data'!F3:F27),0) -> 0 | G23: Refreshed from DJ Wear Tenancy Schedule as at 31.7.2026: corrected rent review dates/types for TJC#1 (Balance Insolvency), Pinpoint Talent, Hilliard & Berry, and Aitken Investment Mgmt to match latest TS; renamed suite 1103 tenant from "Inferni Systems" to correct name "Interfi Systems" and confirmed nil Outgoings/Car Parks for that suite. Lewis Woolcott (1102, new lease from 15/8/26) still pending TS confirmation of rent — no financial detail issued yet.
B41: MONTHLY UPDATE CHECKLIST
B42: 1 | C42: Download DJ Wear Tenancy Schedule PDF from property management system
B43: 2 | C43: Update Input Data tab — check each row for rent, dates, PSM, incentive changes
B44: 3 | C44: Update Market Rents 26-27 tab if any market adjustments since last review
B45: 4 | C45: Review Dashboard — confirm KPIs reconcile with schedule totals
B46: 5 | C46: Update Expiry Profile — check any new leases or surrenders
B47: 6 | C47: Update Leasing Activity tab with any new deals, HOAs or renewals
B48: 7 | C48: Update Make Good Obligations — check notice periods and estimated costs
B49: 8 | C49: Update Spec Fitouts tab with any new capex approvals or completions
B50: 9 | C50: Fill in Update Log above with date, occupancy, WALE and key changes
B51: 10 | C51: Save file with month-year in filename (e.g. 17Castlereagh_May26.xlsx)

Sheet Input Data
A1: 17 CASTLEREAGH ST, SYDNEY — TENANCY SCHEDULE INPUT | As at 31.7.2026
A2: Suite ID | B2: Floor | C2: Suite # | D2: Tenant Name | E2: Trading Name | F2: NLA (sqm) | G2: Lease Start | H2: Lease Expiry | I2: Term (Yrs) | J2: PSM (Face) | K2: Office Rent PA ($) | L2: Incentive Rent PA ($) | M2: Outgoings PA ($) | N2: Net Rent PA ($) | O2: Car Parks | P2: Review Type | Q2: Next Review Date | R2: Outgoings Type | S2: Market Rent PSM ($) | T2: Variance to Mkt ($) | U2: Variance to Mkt (%) | V2: WALE (yrs) | W2: Weighted NLA | X2: Notes | Y2: Status | Z2: Expiry Date (Source — Enter Here) | AA2: PSM Src | AB2: Display Name
A3: 00001 | B3: BSMT | C3: LWR GROUND | D3: =IF(Y3="EXPIRED","VACANT","OPULENT TWO ENTERPRISES") -> OPULENT TWO ENTERPRISES | E3: =IF(Y3="EXPIRED","","OPULENT TWO ENTERPRISES") -> OPULENT TWO ENTERPRISES | F3: 151.2 | G3: =IF(Y3="EXPIRED","",DATE(2016,2,1)) -> 42401 | H3: =IF(Z3="","",IF(Z3<TODAY(),"",Z3)) -> 47149 | I3: =IF(Y3="EXPIRED","",13) -> 13 | J3: =IF(Y3="EXPIRED",0,1002.01) -> 1002.01 | K3: =IF(Y3="EXPIRED",0,J3*F3) -> 151503.91 | L3: -28014.84 | M3: 15000 | N3: =K3+L3 -> 123489.07 | O3: 0 | P3: FIXED 4% | Q3: 46419 | R3: Net | S3: =IFERROR(INDEX('Market Rents 26-27'!E:E,MATCH(C3,'Market Rents 26-27'!$A:$A,0)),0) -> 930 | T3: =IF(J3>0,J3-S3,"") -> 72.01 | U3: =IF(AND(J3>0,S3>0),(J3-S3)/S3,"") -> 0.077430108 | V3: =IF(H3="",0,IFERROR(MAX((H3-TODAY())/365.25,0),0)) -> 2.294319 | W3: =F3*V3 -> 346.90103 | Y3: =IF(Z3="","VACANT",IF(Z3<TODAY(),"EXPIRED","ACTIVE")) -> ACTIVE | Z3: 47149 | AA3: 1002.01 | AB3: Opulent Two Enterprises
A4: 00002 | B4: GF | C4: GROUND | D4: =IF(Y4="EXPIRED","VACANT","RCVRI MARTIN PLACE PTY LTD") -> RCVRI MARTIN PLACE PTY LTD | E4: =IF(Y4="EXPIRED","","RECOVERIE") -> RECOVERIE | F4: 298.3 | G4: =IF(Y4="EXPIRED","",DATE(2025,1,21)) -> 45678 | H4: =IF(Z4="","",IF(Z4<TODAY(),"",Z4)) -> 48233 | I4: =IF(Y4="EXPIRED","",7) -> 7 | J4: =IF(Y4="EXPIRED",0,1150.52) -> 1150.52 | K4: =IF(Y4="EXPIRED",0,J4*F4) -> 343200.12 | L4: -70714.32 | M4: 10408.32 | N4: =K4+L4 -> 272485.8 | O4: 0 | P4: FIXED 4% | Q4: 46408 | R4: Gross | S4: =IFERROR(INDEX('Market Rents 26-27'!E:E,MATCH(C4,'Market Rents 26-27'!$A:$A,0)),0) -> 1100 | T4: =IF(J4>0,J4-S4,"") -> 50.52 | U4: =IF(AND(J4>0,S4>0),(J4-S4)/S4,"") -> 0.045927273 | V4: =IF(H4="",0,IFERROR(MAX((H4-TODAY())/365.25,0),0)) -> 5.2621492 | W4: =F4*V4 -> 1569.6991 | Y4: =IF(Z4="","VACANT",IF(Z4<TODAY(),"EXPIRED","ACTIVE")) -> ACTIVE | Z4: 48233 | AA4: 1150.52 | AB4: Recoverie
A5: 00005 | B5: L01 | C5: 101&2 | D5: VACANT | F5: 162.4 | H5: =IF(Z5="","",IF(Z5<TODAY(),"",Z5)) | I5: =IF(Y5="EXPIRED","",3) -> 3 | K5: =IF(Y5="EXPIRED",0,J5*F5) -> 0 | L5: 0 | N5: =K5+L5 -> 0 | O5: 0 | S5: =IFERROR(INDEX('Market Rents 26-27'!E:E,MATCH(C5,'Market Rents 26-27'!$A:$A,0)),0) -> 1115 | T5: =IF(J5>0,J5-S5,"") | V5: =IF(H5="",0,IFERROR(MAX((H5-TODAY())/365.25,0),0)) -> 0 | W5: =F5*V5 -> 0 | Y5: =IF(Z5="","VACANT",IF(Z5<TODAY(),"EXPIRED","ACTIVE")) -> VACANT
A6: 00008 | B6: L01 | C6: 103 | D6: =IF(Y6="EXPIRED","VACANT","PU PRIME TRADING PTY LTD") -> PU PRIME TRADING PTY LTD | E6: =IF(Y6="EXPIRED","","PU PRIME TRADING PTY LTD") -> PU PRIME TRADING PTY LTD | F6: 96.3 | G6: =IF(Y6="EXPIRED","",DATE(2021,7,1)) -> 44378 | H6: =IF(Z6="","",IF(Z6<TODAY(),"",Z6)) -> 46918 | I6: =IF(Y6="EXPIRED","",7) -> 7 | J6: 1021.99 | K6: =IF(Y6="EXPIRED",0,J6*F6) -> 98417.637 | L6: -9021.6 | M6: 6780 | N6: =K6+L6 -> 89396.037 | O6: 0 | P6: FIXED 4% | Q6: 46461 | R6: Net | S6: =IFERROR(INDEX('Market Rents 26-27'!E:E,MATCH(C6,'Market Rents 26-27'!$A:$A,0)),0) -> 960 | T6: =IF(J6>0,J6-S6,"") -> 61.99 | U6: =IF(AND(J6>0,S6>0),(J6-S6)/S6,"") -> 0.064572917 | V6: =IF(H6="",0,IFERROR(MAX((H6-TODAY())/365.25,0),0)) -> 1.6618754 | W6: =F6*V6 -> 160.0386 | Y6: =IF(Z6="","VACANT",IF(Z6<TODAY(),"EXPIRED","ACTIVE")) -> ACTIVE | Z6: 46918 | AA6: 1021.99 | AB6: PU Prime Trading
A7: 00009 | B7: L01 | C7: 104 | D7: =IF(Y7="EXPIRED","VACANT","TJC#1 PTY LTD") -> TJC#1 PTY LTD | E7: =IF(Y7="EXPIRED","","BALANCE INSOLVENCY") -> BALANCE INSOLVENCY | F7: 98.1 | G7: =IF(Y7="EXPIRED","",DATE(2023,8,1)) -> 45139 | H7: =IF(Z7="","",IF(Z7<TODAY(),"",Z7)) -> 47330 | I7: =IF(Y7="EXPIRED","",3) -> 3 | J7: =IF(Y7="EXPIRED",0,973.44) -> 973.44 | K7: =IF(Y7="EXPIRED",0,J7*F7) -> 95494.464 | L7: -19423.8 | M7: 4500 | N7: =K7+L7 -> 76070.664 | O7: 0 | P7: FIXED 4% | Q7: 46600 | R7: Net | S7: =IFERROR(INDEX('Market Rents 26-27'!E:E,MATCH(C7,'Market Rents 26-27'!$A:$A,0)),0) -> 960 | T7: =IF(J7>0,J7-S7,"") -> 13.44 | U7: =IF(AND(J7>0,S7>0),(J7-S7)/S7,"") -> 0.014 | V7: =IF(H7="",0,IFERROR(MAX((H7-TODAY())/365.25,0),0)) -> 2.78987 | W7: =F7*V7 -> 273.68624 | Y7: =IF(Z7="","VACANT",IF(Z7<TODAY(),"EXPIRED","ACTIVE")) -> ACTIVE | Z7: 47330 | AA7: 973.44 | AB7: TJC#1
A8: 00012 | B8: L02 | C8: WHOLE | D8: =IF(Y8="EXPIRED","VACANT","PRINCETON FINANCIAL SERVICES") -> PRINCETON FINANCIAL SERVICES | E8: =IF(Y8="EXPIRED","","PRINCETON FINANCIAL SERVICES") -> PRINCETON FINANCIAL SERVICES | F8: 393.2 | G8: =IF(Y8="EXPIRED","",DATE(2024,1,1)) -> 45292 | H8: =IF(Z8="","",IF(Z8<TODAY(),"",Z8)) -> 47118 | I8: =IF(Y8="EXPIRED","",5) -> 5 | J8: =IF(Y8="EXPIRED",0,1081.6) -> 1081.6 | K8: =IF(Y8="EXPIRED",0,J8*F8) -> 425285.12 | L8: -23581.8 | M8: 16200 | N8: =K8+L8 -> 401703.32 | O8: 0 | P8: FIXED 4% | Q8: 46388 | R8: Net | S8: =IFERROR(INDEX('Market Rents 26-27'!E:E,MATCH(C8,'Market Rents 26-27'!$A:$A,0)),0) -> 1095 | T8: =IF(J8>0,J8-S8,"") -> -13.4 | U8: =IF(AND(J8>0,S8>0),(J8-S8)/S8,"") -> -0.012237443 | V8: =IF(H8="",0,IFERROR(MAX((H8-TODAY())/365.25,0),0)) -> 2.2094456 | W8: =F8*V8 -> 868.754 | Y8: =IF(Z8="","VACANT",IF(Z8<TODAY(),"EXPIRED","ACTIVE")) -> ACTIVE | Z8: 47118 | AA8: 1081.6 | AB8: Princeton Financial Services
A9: 00015 | B9: L03 | C9: 301&2 | D9: =IF(Y9="EXPIRED","VACANT","IPM RESIDENTIAL PTY LTD") -> IPM RESIDENTIAL PTY LTD | E9: =IF(Y9="EXPIRED","","IPM RESIDENTIAL PTY LTD") -> IPM RESIDENTIAL PTY LTD | F9: 164.2 | G9: =IF(Y9="EXPIRED","",DATE(2022,6,1)) -> 44713 | H9: =IF(Z9="","",IF(Z9<TODAY(),"",Z9)) -> 46538 | I9: =IF(Y9="EXPIRED","",5) -> 5 | J9: 1216.58 | K9: =IF(Y9="EXPIRED",0,J9*F9) -> 199762.44 | L9: -15516.96 | M9: 9900 | N9: =K9+L9 -> 184245.48 | O9: 2 | P9: LEASE RENEWAL | Q9: 46539 | R9: Net | S9: =IFERROR(INDEX('Market Rents 26-27'!E:E,MATCH(C9,'Market Rents 26-27'!$A:$A,0)),0) -> 1135 | T9: =IF(J9>0,J9-S9,"") -> 81.58 | U9: =IF(AND(J9>0,S9>0),(J9-S9)/S9,"") -> 0.071876652 | V9: =IF(H9="",0,IFERROR(MAX((H9-TODAY())/365.25,0),0)) -> 0.62149213 | W9: =F9*V9 -> 102.04901 | Y9: =IF(Z9="","VACANT",IF(Z9<TODAY(),"EXPIRED","ACTIVE")) -> ACTIVE | Z9: 46538 | AA9: 1216.58 | AB9: IPM Residential
A10: 00018 | B10: L03 | C10: 303&4 | D10: =IF(Y10="EXPIRED","VACANT","BROADRIDGE (AUSTRALIA) PTY LTD") -> BROADRIDGE (AUSTRALIA) PTY LTD | E10: =IF(Y10="EXPIRED","","BROADRIDGE (AUSTRALI) PTY LTD") -> BROADRIDGE (AUSTRALI) PTY LTD | F10: 193.4 | G10: =IF(Y10="EXPIRED","",DATE(2024,10,1)) -> 45566 | H10: =IF(Z10="","",IF(Z10<TODAY(),"",Z10)) -> 47026 | I10: =IF(Y10="EXPIRED","",4) -> 4 | J10: =IF(Y10="EXPIRED",0,933.75) -> 933.75 | K10: =IF(Y10="EXPIRED",0,J10*F10) -> 180587.25 | L10: -20962.2 | M10: 6300 | N10: =K10+L10 -> 159625.05 | O10: 0 | P10: FIXED 3.75% | Q10: 46296 | R10: Net | S10: =IFERROR(INDEX('Market Rents 26-27'!E:E,MATCH(C10,'Market Rents 26-27'!$A:$A,0)),0) -> 920 | T10: =IF(J10>0,J10-S10,"") -> 13.75 | U10: =IF(AND(J10>0,S10>0),(J10-S10)/S10,"") -> 0.014945652 | V10: =IF(H10="",0,IFERROR(MAX((H10-TODAY())/365.25,0),0)) -> 1.9575633 | W10: =F10*V10 -> 378.59274 | Y10: =IF(Z10="","VACANT",IF(Z10<TODAY(),"EXPIRED","ACTIVE")) -> ACTIVE | Z10: 47026 | AA10: 933.75 | AB10: Broadridge
A11: 00021 | B11: L04 | C11: 401 | D11: =IF(Y11="EXPIRED","VACANT","B-W INTERNATIONAL AUSTRALIA PTY LTD") -> B-W INTERNATIONAL AUSTRALIA PTY LTD | E11: =IF(Y11="EXPIRED","","B-W INTERNATIONAL AUSTRALIA PTY LTD") -> B-W INTERNATIONAL AUSTRALIA PTY LTD | F11: 214.1 | G11: =IF(Y11="EXPIRED","",DATE(2024,3,1)) -> 45352 | H11: =IF(Z11="","",IF(Z11<TODAY(),"",Z11)) -> 47177 | I11: =IF(Y11="EXPIRED","",5) -> 5 | J11: =IF(Y11="EXPIRED",0,1135.61) -> 1135.61 | K11: =IF(Y11="EXPIRED",0,J11*F11) -> 243134.1 | L11: -54203.76 | M11: 8700 | N11: =K11+L11 -> 188930.34 | O11: 0 | P11: FIXED 3.75% | Q11: 46447 | R11: Net | S11: =IFERROR(INDEX('Market Rents 26-27'!E:E,MATCH(C11,'Market Rents 26-27'!$A:$A,0)),0) -> 1145 | T11: =IF(J11>0,J11-S11,"") -> -9.39 | U11: =IF(AND(J11>0,S11>0),(J11-S11)/S11,"") -> -0.0082008734 | V11: =IF(H11="",0,IFERROR(MAX((H11-TODAY())/365.25,0),0)) -> 2.3709788 | W11: =F11*V11 -> 507.62656 | Y11: =IF(Z11="","VACANT",IF(Z11<TODAY(),"EXPIRED","ACTIVE")) -> ACTIVE | Z11: 47177 | AA11: 1135.61 | AB11: B-W International
A12: 00022 | B12: L04 | C12: 402 | D12: =IF(Y12="EXPIRED","VACANT","MP TRAVEL PTY LTD") -> MP TRAVEL PTY LTD | E12: =IF(Y12="EXPIRED","","GRAY DAWES TRAVEL") -> GRAY DAWES TRAVEL | F12: 145.6 | G12: =IF(Y12="EXPIRED","",DATE(2025,1,1)) -> 45658 | H12: =IF(Z12="","",IF(Z12<TODAY(),"",Z12)) -> 47483 | I12: =IF(Y12="EXPIRED","",5) -> 5 | J12: =IF(Y12="EXPIRED",0,1037.5) -> 1037.5 | K12: =IF(Y12="EXPIRED",0,J12*F12) -> 151060 | L12: -17675.88 | M12: 6000 | N12: =K12+L12 -> 133384.12 | O12: 0 | P12: FIXED 3.75% | Q12: 46388 | R12: Net | S12: =IFERROR(INDEX('Market Rents 26-27'!E:E,MATCH(C12,'Market Rents 26-27'!$A:$A,0)),0) -> 1000 | T12: =IF(J12>0,J12-S12,"") -> 37.5 | U12: =IF(AND(J12>0,S12>0),(J12-S12)/S12,"") -> 0.0375 | V12: =IF(H12="",0,IFERROR(MAX((H12-TODAY())/365.25,0),0)) -> 3.2087611 | W12: =F12*V12 -> 467.19562 | Y12: =IF(Z12="","VACANT",IF(Z12<TODAY(),"EXPIRED","ACTIVE")) -> ACTIVE | Z12: 47483 | AA12: 1037.5 | AB12: Gray Dawes Travel
A13: 00025 | B13: L05 | C13: 501 | D13: =IF(Y13="EXPIRED","VACANT","MONTGOMERY INVESTMENT") -> MONTGOMERY INVESTMENT | E13: =IF(Y13="EXPIRED","","MONTGOMERY INVESTMENT") -> MONTGOMERY INVESTMENT | F13: 212.3 | G13: =IF(Y13="EXPIRED","",DATE(2019,11,1)) -> 43770 | H13: =IF(Z13="","",IF(Z13<TODAY(),"",Z13)) -> 46691 | I13: =IF(Y13="EXPIRED","",8) -> 8 | J13: =IF(Y13="EXPIRED",0,1341.24) -> 1341.24 | K13: =IF(Y13="EXPIRED",0,J13*F13) -> 284745.25 | L13: -49361.76 | M13: 9900 | N13: =K13+L13 -> 235383.49 | O13: 0 | P13: FIXED 4% | Q13: 46327 | R13: Net | S13: =IFERROR(INDEX('Market Rents 26-27'!E:E,MATCH(C13,'Market Rents 26-27'!$A:$A,0)),0) -> 1155 | T13: =IF(J13>0,J13-S13,"") -> 186.24 | U13: =IF(AND(J13>0,S13>0),(J13-S13)/S13,"") -> 0.16124675 | V13: =IF(H13="",0,IFERROR(MAX((H13-TODAY())/365.25,0),0)) -> 1.0403833 | W13: =F13*V13 -> 220.87337 | Y13: =IF(Z13="","VACANT",IF(Z13<TODAY(),"EXPIRED","ACTIVE")) -> ACTIVE | Z13: 46691 | AA13: 1341.24 | AB13: Montgomery Investment
A14: 00026 | B14: L05 | C14: 502 | D14: =IF(Y14="EXPIRED","VACANT","THREAT DEFENCE") -> THREAT DEFENCE | E14: =IF(Y14="EXPIRED","","THREAT DEFENCE PTY LTD") -> THREAT DEFENCE PTY LTD | F14: 163.8 | G14: =IF(Y14="EXPIRED","",DATE(2024,7,1)) -> 45474 | H14: =IF(Z14="","",IF(Z14<TODAY(),"",Z14)) -> 46568 | I14: =IF(Y14="EXPIRED","",3) -> 3 | J14: 1054.88 | K14: =IF(Y14="EXPIRED",0,J14*F14) -> 172789.34 | L14: -41736.24 | M14: 7140 | N14: =K14+L14 -> 131053.1 | O14: 0 | P14: LEASE RENEWAL | Q14: 46569 | R14: Net | S14: =IFERROR(INDEX('Market Rents 26-27'!E:E,MATCH(C14,'Market Rents 26-27'!$A:$A,0)),0) -> 1020 | T14: =IF(J14>0,J14-S14,"") -> 34.88 | U14: =IF(AND(J14>0,S14>0),(J14-S14)/S14,"") -> 0.034196078 | V14: =IF(H14="",0,IFERROR(MAX((H14-TODAY())/365.25,0),0)) -> 0.70362765 | W14: =F14*V14 -> 115.25421 | Y14: =IF(Z14="","VACANT",IF(Z14<TODAY(),"EXPIRED","ACTIVE")) -> ACTIVE | Z14: 46568 | AA14: 1054.88 | AB14: Threat Defence
A15: 00029 | B15: L06 | C15: 601 | D15: =IF(Y15="EXPIRED","VACANT","FULLCRM PTY LTD") -> FULLCRM PTY LTD | E15: =IF(Y15="EXPIRED","","FULLCRM PTY LTD") -> FULLCRM PTY LTD | F15: 226.1 | G15: =IF(Y15="EXPIRED","",DATE(2021,12,1)) -> 44531 | H15: =IF(Z15="","",IF(Z15<TODAY(),"",Z15)) -> 46418 | I15: =IF(Y15="EXPIRED","",5.2) -> 5.2 | J15: =IF(Y15="EXPIRED",0,1251.34) -> 1251.34 | K15: =IF(Y15="EXPIRED",0,J15*F15) -> 282927.97 | L15: -31744.44 | M15: 13800 | N15: =K15+L15 -> 251183.53 | O15: 0 | P15: LEASE RENEWAL | Q15: 46419 | R15: Net | S15: =IFERROR(INDEX('Market Rents 26-27'!E:E,MATCH(C15,'Market Rents 26-27'!$A:$A,0)),0) -> 1165 | T15: =IF(J15>0,J15-S15,"") -> 86.34 | U15: =IF(AND(J15>0,S15>0),(J15-S15)/S15,"") -> 0.074111588 | V15: =IF(H15="",0,IFERROR(MAX((H15-TODAY())/365.25,0),0)) -> 0.29295003 | W15: =F15*V15 -> 66.236003 | Y15: =IF(Z15="","VACANT",IF(Z15<TODAY(),"EXPIRED","ACTIVE")) -> ACTIVE | Z15: 46418 | AA15: 1251.34 | AB15: Fullcrm
A16: 00030 | B16: L06 | C16: 602 | D16: INNOVIS | E16: INNOVIS | F16: 152.1 | G16: 46327 | H16: =IF(Z16="","",IF(Z16<TODAY(),"",Z16)) -> 47421 | I16: 3 | J16: 1090 | K16: =IF(Y16="EXPIRED",0,J16*F16) -> 165789 | L16: -29842.02 | N16: =K16+L16 -> 135946.98 | O16: 0 | P16: FIXED 3.75% | Q16: 46692 | R16: Net | S16: =IFERROR(INDEX('Market Rents 26-27'!E:E,MATCH(C16,'Market Rents 26-27'!$A:$A,0)),0) -> 1030 | T16: =IF(J16>0,J16-S16,"") -> 60 | U16: =IF(AND(J16>0,S16>0),(J16-S16)/S16,"") -> 0.058252427 | V16: =IF(H16="",0,IFERROR(MAX((H16-TODAY())/365.25,0),0)) -> 3.0390144 | W16: =F16*V16 -> 462.23409 | Y16: =IF(Z16="","VACANT",IF(Z16<TODAY(),"EXPIRED","ACTIVE")) -> ACTIVE | Z16: 47421 | AA16: 756.36 | AB16: INNOVIS
A17: 00033 | B17: L07 | C17: 701 | D17: =IF(Y17="EXPIRED","VACANT","PINPOINT TALENT PTY LTD") -> PINPOINT TALENT PTY LTD | E17: =IF(Y17="EXPIRED","","PINPOINT TALENT PTY LTD") -> PINPOINT TALENT PTY LTD | F17: 210.5 | G17: =IF(Y17="EXPIRED","",DATE(2023,8,7)) -> 45145 | H17: =IF(Z17="","",IF(Z17<TODAY(),"",Z17)) -> 46605 | I17: =IF(Y17="EXPIRED","",4) -> 4 | J17: =IF(Y17="EXPIRED",0,1173.54) -> 1173.54 | K17: =IF(Y17="EXPIRED",0,J17*F17) -> 247030.17 | L17: -68517.72 | M17: 13800 | N17: =K17+L17 -> 178512.45 | O17: 0 | P17: LEASE RENEWAL | Q17: 46606 | R17: Net | S17: =IFERROR(INDEX('Market Rents 26-27'!E:E,MATCH(C17,'Market Rents 26-27'!$A:$A,0)),0) -> 1175 | T17: =IF(J17>0,J17-S17,"") -> -1.46 | U17: =IF(AND(J17>0,S17>0),(J17-S17)/S17,"") -> -0.0012425532 | V17: =IF(H17="",0,IFERROR(MAX((H17-TODAY())/365.25,0),0)) -> 0.80492813 | W17: =F17*V17 -> 169.43737 | Y17: =IF(Z17="","VACANT",IF(Z17<TODAY(),"EXPIRED","ACTIVE")) -> ACTIVE | Z17: 46605 | AA17: 1173.54 | AB17: Pinpoint Talent
A18: 00034 | B18: L07 | C18: 702 | D18: =IF(Y18="EXPIRED","VACANT","SATELLITE OFFICE PTY LTD") -> SATELLITE OFFICE PTY LTD | E18: =IF(Y18="EXPIRED","","SATELLITE OFFICE PTY LTD") -> SATELLITE OFFICE PTY LTD | F18: 163.9 | G18: =IF(Y18="EXPIRED","",DATE(2024,6,1)) -> 45444 | H18: =IF(Z18="","",IF(Z18<TODAY(),"",Z18)) -> 46904 | I18: =IF(Y18="EXPIRED","",4) -> 4 | J18: 1054.88 | K18: =IF(Y18="EXPIRED",0,J18*F18) -> 172894.83 | L18: -40261.56 | M18: 7020 | N18: =K18+L18 -> 132633.27 | O18: 0 | P18: FIXED 3.75% | Q18: 46539 | R18: Net | S18: =IFERROR(INDEX('Market Rents 26-27'!E:E,MATCH(C18,'Market Rents 26-27'!$A:$A,0)),0) -> 1040 | T18: =IF(J18>0,J18-S18,"") -> 14.88 | U18: =IF(AND(J18>0,S18>0),(J18-S18)/S18,"") -> 0.014307692 | V18: =IF(H18="",0,IFERROR(MAX((H18-TODAY())/365.25,0),0)) -> 1.6235455 | W18: =F18*V18 -> 266.09911 | Y18: =IF(Z18="","VACANT",IF(Z18<TODAY(),"EXPIRED","ACTIVE")) -> ACTIVE | Z18: 46904 | AA18: 1054.88 | AB18: Satellite Office
A19: 00037 | B19: L08 | C19: 801 | D19: =IF(Y19="EXPIRED","VACANT","ARKANCE AUSTRALIA PTY LTD") -> ARKANCE AUSTRALIA PTY LTD | E19: =IF(Y19="EXPIRED","","ARKANCE AUSTRALIA PTY LTD") -> ARKANCE AUSTRALIA PTY LTD | F19: 222 | G19: =IF(Y19="EXPIRED","",DATE(2025,10,1)) -> 45931 | H19: =IF(Z19="","",IF(Z19<TODAY(),"",Z19)) -> 47756 | I19: =IF(Y19="EXPIRED","",5) -> 5 | J19: =IF(Y19="EXPIRED",0,1300) -> 1300 | K19: =IF(Y19="EXPIRED",0,J19*F19) -> 288600 | L19: -46176 | M19: 1500 | N19: =K19+L19 -> 242424 | O19: 0 | P19: FIXED 3.75% | Q19: 46296 | R19: Net | S19: =IFERROR(INDEX('Market Rents 26-27'!E:E,MATCH(C19,'Market Rents 26-27'!$A:$A,0)),0) -> 1300 | T19: =IF(J19>0,J19-S19,"") -> 0 | U19: =IF(AND(J19>0,S19>0),(J19-S19)/S19,"") -> 0 | V19: =IF(H19="",0,IFERROR(MAX((H19-TODAY())/365.25,0),0)) -> 3.9561944 | W19: =F19*V19 -> 878.27515 | Y19: =IF(Z19="","VACANT",IF(Z19<TODAY(),"EXPIRED","ACTIVE")) -> ACTIVE | Z19: 47756 | AA19: 1300 | AB19: Arkance Australia
A20: 00038 | B20: L08 | C20: 802 | D20: =IF(Y20="EXPIRED","VACANT","HILLIARD & BERRY") -> HILLIARD & BERRY | E20: =IF(Y20="EXPIRED","","HILLIARD & BERRY") -> HILLIARD & BERRY | F20: 138.5 | G20: =IF(Y20="EXPIRED","",DATE(2014,1,15)) -> 41654 | H20: =IF(Z20="","",IF(Z20<TODAY(),"",Z20)) -> 46965 | I20: =IF(Y20="EXPIRED","",14.6) -> 14.6 | J20: =IF(Y20="EXPIRED",0,843.65) -> 843.65 | K20: =IF(Y20="EXPIRED",0,J20*F20) -> 116845.52 | L20: 0 | M20: 12240 | N20: =K20+L20 -> 116845.52 | O20: 0 | P20: FIXED 4% | Q20: 46600 | R20: Net | S20: =IFERROR(INDEX('Market Rents 26-27'!E:E,MATCH(C20,'Market Rents 26-27'!$A:$A,0)),0) -> 1030 | T20: =IF(J20>0,J20-S20,"") -> -186.35 | U20: =IF(AND(J20>0,S20>0),(J20-S20)/S20,"") -> -0.18092233 | V20: =IF(H20="",0,IFERROR(MAX((H20-TODAY())/365.25,0),0)) -> 1.7905544 | W20: =F20*V20 -> 247.99179 | Y20: =IF(Z20="","VACANT",IF(Z20<TODAY(),"EXPIRED","ACTIVE")) -> ACTIVE | Z20: 46965 | AA20: 843.65 | AB20: Hilliard & Berry
A21: 00041 | B21: L09 | C21: 901 | D21: =IF(Y21="EXPIRED","VACANT","AITKEN INVESTMENT MANAGEMENT PTY LTD") -> AITKEN INVESTMENT MANAGEMENT PTY LTD | E21: =IF(Y21="EXPIRED","","AITKEN INVESTMENT MANAGEMENT") -> AITKEN INVESTMENT MANAGEMENT | F21: 52.8 | G21: =IF(Y21="EXPIRED","",DATE(2025,6,15)) -> 45823 | H21: =IF(Z21="","",IF(Z21<TODAY(),"",Z21)) -> 46918 | I21: =IF(Y21="EXPIRED","",3) -> 3 | J21: 1338.88 | K21: =IF(Y21="EXPIRED",0,J21*F21) -> 70692.864 | L21: -16394.4 | M21: 3780 | N21: =K21+L21 -> 54298.464 | O21: 0 | P21: FIXED 4% | Q21: 46918 | R21: Net | S21: =IFERROR(INDEX('Market Rents 26-27'!E:E,MATCH(C21,'Market Rents 26-27'!$A:$A,0)),0) -> 1350 | T21: =IF(J21>0,J21-S21,"") -> -11.12 | U21: =IF(AND(J21>0,S21>0),(J21-S21)/S21,"") -> -0.008237037 | V21: =IF(H21="",0,IFERROR(MAX((H21-TODAY())/365.25,0),0)) -> 1.6618754 | W21: =F21*V21 -> 87.747023 | Y21: =IF(Z21="","VACANT",IF(Z21<TODAY(),"EXPIRED","ACTIVE")) -> ACTIVE | Z21: 46918 | AA21: 1338.88 | AB21: Aitken Investment Mgmt
A22: 00044 | B22: L09 | C22: 902&3 | D22: =IF(Y22="EXPIRED","VACANT","CAPITAL E MARKETING AND EVENTS PTY LTD") -> CAPITAL E MARKETING AND EVENTS PTY LTD | E22: =IF(Y22="EXPIRED","","CAPITAL E MARKETING AND EVENTS") -> CAPITAL E MARKETING AND EVENTS | F22: 303 | G22: =IF(Y22="EXPIRED","",DATE(2022,1,1)) -> 44562 | H22: =IF(Z22="","",IF(Z22<TODAY(),"",Z22)) -> 47573 | I22: =IF(Y22="EXPIRED","",8.2) -> 8.2 | J22: =IF(Y22="EXPIRED",0,1141.25) -> 1141.25 | K22: =IF(Y22="EXPIRED",0,J22*F22) -> 345798.75 | L22: -90475.68 | M22: 9300 | N22: =K22+L22 -> 255323.07 | O22: 0 | P22: FIXED 3.75% | Q22: 46478 | R22: Net | S22: =IFERROR(INDEX('Market Rents 26-27'!E:E,MATCH(C22,'Market Rents 26-27'!$A:$A,0)),0) -> 1125 | T22: =IF(J22>0,J22-S22,"") -> 16.25 | U22: =IF(AND(J22>0,S22>0),(J22-S22)/S22,"") -> 0.014444444 | V22: =IF(H22="",0,IFERROR(MAX((H22-TODAY())/365.25,0),0)) -> 3.4551677 | W22: =F22*V22 -> 1046.9158 | Y22: =IF(Z22="","VACANT",IF(Z22<TODAY(),"EXPIRED","ACTIVE")) -> ACTIVE | Z22: 47573 | AA22: 1141.25 | AB22: Capital E Marketing
A23: 00048 | B23: L10 | C23: 1001&2 | D23: =IF(Y23="EXPIRED","VACANT","CONNECTUS SERVICES PTY LTD") -> CONNECTUS SERVICES PTY LTD | E23: =IF(Y23="EXPIRED","","CONNECTUS") -> CONNECTUS | F23: 363.2 | G23: =IF(Y23="EXPIRED","",DATE(2023,12,1)) -> 45261 | H23: =IF(Z23="","",IF(Z23<TODAY(),"",Z23)) -> 47452 | I23: =IF(Y23="EXPIRED","",6) -> 6 | J23: =IF(Y23="EXPIRED",0,1189.67) -> 1189.67 | K23: =IF(Y23="EXPIRED",0,J23*F23) -> 432088.14 | L23: -114537.96 | M23: 15000 | N23: =K23+L23 -> 317550.18 | O23: 0 | P23: FIXED | Q23: 46357 | R23: Net | S23: =IFERROR(INDEX('Market Rents 26-27'!E:E,MATCH(C23,'Market Rents 26-27'!$A:$A,0)),0) -> 1200 | T23: =IF(J23>0,J23-S23,"") -> -10.33 | U23: =IF(AND(J23>0,S23>0),(J23-S23)/S23,"") -> -0.0086083333 | V23: =IF(H23="",0,IFERROR(MAX((H23-TODAY())/365.25,0),0)) -> 3.1238877 | W23: =F23*V23 -> 1134.596 | Y23: =IF(Z23="","VACANT",IF(Z23<TODAY(),"EXPIRED","ACTIVE")) -> ACTIVE | Z23: 47452 | AA23: 1189.67 | AB23: Connectus Services
A24: 00050 | B24: L11 | C24: 1101 | D24: =IF(Y24="EXPIRED","VACANT","MICHAEL FLEGG PTY LTD") -> MICHAEL FLEGG PTY LTD | E24: =IF(Y24="EXPIRED","","MICHAEL FLEGG PTY LTD") -> MICHAEL FLEGG PTY LTD | F24: 62.4 | G24: =IF(Y24="EXPIRED","",DATE(2021,12,1)) -> 44531 | H24: =IF(Z24="","",IF(Z24<TODAY(),"",Z24)) -> 46356 | I24: =IF(Y24="EXPIRED","",5) -> 5 | J24: =IF(Y24="EXPIRED",0,1368.73) -> 1368.73 | K24: =IF(Y24="EXPIRED",0,J24*F24) -> 85408.752 | L24: 0 | M24: 4200 | N24: =K24+L24 -> 85408.752 | O24: 0 | P24: LEASE RENEWAL | Q24: 46357 | R24: Net | S24: =IFERROR(INDEX('Market Rents 26-27'!E:E,MATCH(C24,'Market Rents 26-27'!$A:$A,0)),0) -> 1405 | T24: =IF(J24>0,J24-S24,"") -> -36.27 | U24: =IF(AND(J24>0,S24>0),(J24-S24)/S24,"") -> -0.025814947 | V24: =IF(H24="",0,IFERROR(MAX((H24-TODAY())/365.25,0),0)) -> 0.12320329 | W24: =F24*V24 -> 7.687885 | Y24: =IF(Z24="","VACANT",IF(Z24<TODAY(),"EXPIRED","ACTIVE")) -> ACTIVE | Z24: 46356 | AA24: 1368.73 | AB24: Michael Flegg
A25: 00051 | B25: L11 | C25: 1102 | D25: =IF(Y25="EXPIRED","VACANT","LEWIS WOOLCOTT") -> LEWIS WOOLCOTT | E25: =IF(Y25="EXPIRED","","LEWIS WOOLCOTT") -> LEWIS WOOLCOTT | F25: 133.1 | G25: =IF(Y25="EXPIRED","",DATE(2026,8,15)) -> 46249 | H25: =IF(Z25="","",IF(Z25<TODAY(),"",Z25)) -> 46979 | I25: =IF(Y25="EXPIRED","",2) -> 2 | J25: =IF(Y25="EXPIRED",0,1271.1) -> 1271.1 | K25: =IF(Y25="EXPIRED",0,J25*F25) -> 169183.41 | L25: -30453.01 | M25: 5820 | N25: =K25+L25 -> 138730.4 | O25: 0 | P25: FIXED 4.0% | Q25: 46614 | R25: Net | S25: =IFERROR(INDEX('Market Rents 26-27'!E:E,MATCH(C25,'Market Rents 26-27'!$A:$A,0)),0) -> 1250 | T25: =IF(J25>0,J25-S25,"") -> 21.1 | U25: =IF(AND(J25>0,S25>0),(J25-S25)/S25,"") -> 0.01688 | V25: =IF(H25="",0,IFERROR(MAX((H25-TODAY())/365.25,0),0)) -> 1.8288843 | W25: =F25*V25 -> 243.4245 | X25: Lewis Woolcott new lease commences 15/8/26 (day after PharmX's lease ends), 2 yr term to 14/8/28, $1,271.10 psm. Outgoings carried forward at PharmX's existing rate pending TS confirmation. | Y25: =IF(Z25="","VACANT",IF(Z25<TODAY(),"EXPIRED","ACTIVE")) -> ACTIVE | Z25: 46979 | AA25: 1271.1 | AB25: Lewis Woolcott
A26: 00055 | B26: L12 | C26: L12 | D26: =IF(Y26="EXPIRED","VACANT","DAKOTA CORPORATION") -> DAKOTA CORPORATION | E26: =IF(Y26="EXPIRED","","OWNER OCCUPIED") -> OWNER OCCUPIED | F26: 223.7 | G26: =IF(Y26="EXPIRED","",DATE(2017,1,1)) -> 42736 | H26: =IF(Z26="","",IF(Z26<TODAY(),"",Z26)) -> 47118 | I26: =IF(Y26="EXPIRED","",7) -> 7 | J26: 0 | K26: =IF(Y26="EXPIRED",0,J26*F26) -> 0 | L26: 0 | M26: 0 | N26: =K26+L26 -> 0 | O26: 2 | P26: MONTHLY TENANT | Q26: 45291 | R26: N/A | S26: =IFERROR(INDEX('Market Rents 26-27'!E:E,MATCH(C26,'Market Rents 26-27'!$A:$A,0)),0) -> 384 | T26: =IF(J26>0,J26-S26,"") | U26: =IF(AND(J26>0,S26>0),(J26-S26)/S26,"") | V26: =IF(H26="",0,IFERROR(MAX((H26-TODAY())/365.25,0),0)) -> 2.2094456 | W26: =F26*V26 -> 494.25298 | Y26: =IF(Z26="","VACANT",IF(Z26<TODAY(),"EXPIRED","ACTIVE")) -> ACTIVE | Z26: 47118 | AA26: 0 | AB26: Dakota Corporation
A27: 00052 | B27: L11 | C27: 1103 | D27: =IF(Y27="EXPIRED","VACANT","INTERFI SYSTEMS PTY LTD") -> INTERFI SYSTEMS PTY LTD | E27: =IF(Y27="EXPIRED","","INTERFI SYSTEMS") -> INTERFI SYSTEMS | F27: 160.3 | G27: =IF(Y27="EXPIRED","",DATE(2026,7,15)) -> 46218 | H27: =IF(Z27="","",IF(Z27<TODAY(),"",Z27)) -> 47313 | I27: =IF(Y27="EXPIRED","",3) -> 3 | J27: =IF(Y27="EXPIRED",0,1150) -> 1150 | K27: =IF(Y27="EXPIRED",0,J27*F27) -> 184345 | L27: -55303.5 | M27: 0 | N27: =K27+L27 -> 129041.5 | O27: 0 | P27: FIXED 4.0% | Q27: 46583 | R27: Net | S27: =IFERROR(INDEX('Market Rents 26-27'!E:E,MATCH(C27,'Market Rents 26-27'!$A:$A,0)),0) -> 1060 | T27: =IF(J27>0,J27-S27,"") -> 90 | U27: =IF(AND(J27>0,S27>0),(J27-S27)/S27,"") -> 0.08490566 | V27: =IF(H27="",0,IFERROR(MAX((H27-TODAY())/365.25,0),0)) -> 2.7433265 | W27: =F27*V27 -> 439.75524 | X27: Interfi Systems (correct spelling per Jul26 TS, previously recorded as "Inferni Systems") — 3 yr term from 15/7/26 to 14/7/29, $1,150 psm. Jul26 TS confirms no Outgoings Cont or car parks for this suite (cleaning charged separately, not tracked in Outgoings PA column). | Y27: =IF(Z27="","VACANT",IF(Z27<TODAY(),"EXPIRED","ACTIVE")) -> ACTIVE | Z27: 47313 | AA27: 1150 | AB27: Interfi Systems
A28: TOTALS / BUILDING SUMMARY | F28: =SUM(F3:F27) -> 4704.5 | K28: =SUM(K3:K27) -> 4907584.1 | L28: =SUM(L3:L27) -> -873919.45 | M28: =SUM(M3:M27) -> 187288.32 | N28: =SUM(N3:N27) -> 4033664.6 | V28: =IFERROR(SUMPRODUCT(('Input Data'!K3:K27>0)*'Input Data'!F3:F27*MAX(('Input Data'!H3:H27-TODAY())/365.25,0))/SUMPRODUCT(('Input Data'!K3:K27>0)*'Input Data'!F3:F27),0) -> 0 | W28: =SUM(W3:W27) -> 10555.323
A30: LEGEND: | C30: Expired / Vacant | E30: Expiring in 2026 | G30: Active (odd rows)
A31: Note: Blue text = hardcoded input | Black text = formula | Update monthly from DJ Wear Tenancy Schedule PDF

Sheet Dashboard
A1: 17 CASTLEREAGH STREET, SYDNEY — ASSET MANAGEMENT DASHBOARD
A2: As at 31 July 2026 | Data sourced from Input Data tab
B4: TOTAL NLA | D4: OCCUPIED NLA | F4: VACANT NLA | H4: OCCUPANCY | J4: VACANCY RATE | L4: CAR PARKS
B5: =SUM('Input Data'!F3:F27) -> 4704.5 | D5: =SUMPRODUCT(('Input Data'!D3:D27<>"VACANT")*'Input Data'!F3:F27) -> 4542.1 | F5: {=SUMPRODUCT(('Input Data'!D3:D27="VACANT")*'Input Data'!F3:F27)} -> 162.4 | H5: {=SUMPRODUCT(('Input Data'!D3:D27<>"VACANT")*'Input Data'!F3:F27)/SUM('Input Data'!F3:F27)} -> 0.96547986 | J5: =SUMPRODUCT(('Input Data'!D3:D27="VACANT")*'Input Data'!F3:F27)/SUM('Input Data'!F3:F27) -> 0.03452014 | L5: 4 bays
B8: GROSS INCOME PA | D8: NET INCOME PA | F8: INCENTIVE RENT PA | H8: WALE BY NLA | J8: WALE BY INCOME | L8: TOTAL OUTGOINGS %
B9: =SUMPRODUCT(('Input Data'!AA3:AA27>0)*'Input Data'!AA3:AA27*'Input Data'!F3:F27) -> 4856837.4 | D9: =SUM('Input Data'!N3:N27) -> 4033664.6 | F9: =SUM('Input Data'!L3:L27) -> -873919.45 | H9: =IFERROR(SUMPRODUCT(('Input Data'!Z3:Z27>TODAY())*('Input Data'!AA3:AA27>0)*'Input Data'!F3:F27*('Input Data'!Z3:Z27-TODAY())/365.25)/SUMPRODUCT(('Input Data'!Z3:Z27>TODAY())*('Input Data'!AA3:AA27>0)*'Input Data'!F3:F27),0) -> 2.3298144 | J9: =IFERROR(SUMPRODUCT(('Input Data'!Z3:Z27>TODAY())*('Input Data'!AA3:AA27>0)*'Input Data'!AA3:AA27*'Input Data'!F3:F27*('Input Data'!Z3:Z27-TODAY())/365.25)/SUMPRODUCT(('Input Data'!Z3:Z27>TODAY())*('Input Data'!AA3:AA27>0)*'Input Data'!AA3:AA27*'Input Data'!F3:F27),0) -> 2.3123282 | L9: 92.32%
B12: WEIGHTED AVERAGE LEASE EXPIRY (WALE)
B13: Measure | D13: WALE | E13: Basis
B14: WALE by NLA | D14: =IFERROR(SUMPRODUCT(('Input Data'!Z3:Z27>TODAY())*('Input Data'!AA3:AA27>0)*'Input Data'!F3:F27*('Input Data'!Z3:Z27-TODAY())/365.25)/SUMPRODUCT(('Input Data'!Z3:Z27>TODAY())*('Input Data'!AA3:AA27>0)*'Input Data'!F3:F27),0) -> 2.3298144 | E14: Area-weighted avg of remaining lease terms
B15: WALE by Income | D15: =IFERROR(SUMPRODUCT(('Input Data'!Z3:Z27>TODAY())*('Input Data'!AA3:AA27>0)*'Input Data'!AA3:AA27*'Input Data'!F3:F27*('Input Data'!Z3:Z27-TODAY())/365.25)/SUMPRODUCT(('Input Data'!Z3:Z27>TODAY())*('Input Data'!AA3:AA27>0)*'Input Data'!AA3:AA27*'Input Data'!F3:F27),0) -> 2.3123282 | E15: Income-weighted avg of remaining lease terms
B17: LEASE EXPIRY PROFILE — BY INCOME & AREA (5 YEAR FORWARD VIEW)
B18: Expiry Year | C18: Net Income ($) | D18: Income % | E18: NLA (sqm) | F18: Area % | G18: # Leases | H18: Tenants Expiring
B19: 2026 | C19: =SUMPRODUCT(('Input Data'!Z3:Z27<>"")*('Input Data'!Z3:Z27<=DATE(2026,12,31))*('Input Data'!AA3:AA27>0)*'Input Data'!AA3:AA27*'Input Data'!F3:F27) -> 85408.752 | D19: =IFERROR(C19/(SUMPRODUCT(('Input Data'!Z3:Z27>TODAY())*('Input Data'!AA3:AA27>0)*'Input Data'!AA3:AA27*'Input Data'!F3:F27)),0) -> 0.017585261 | E19: =SUMPRODUCT(('Input Data'!Z3:Z27<>"")*('Input Data'!Z3:Z27<=DATE(2026,12,31))*('Input Data'!AA3:AA27>0)*'Input Data'!F3:F27) -> 62.4 | F19: =IFERROR(E19/(SUMPRODUCT(('Input Data'!Z3:Z27>TODAY())*('Input Data'!AA3:AA27>0)*'Input Data'!F3:F27)),0) -> 0.014449796 | G19: =SUMPRODUCT(('Input Data'!Z3:Z27<>"")*('Input Data'!Z3:Z27<=DATE(2026,12,31))*('Input Data'!AA3:AA27>0)*1) -> 1 | H19: =IFERROR(MID(IF(('Input Data'!Z3<>"")*('Input Data'!Z3<=DATE(2026,12,31)),", "&'Input Data'!AB3&" ("&'Input Data'!C3&")","")&IF(('Input Data'!Z4<>"")*('Input Data'!Z4<=DATE(2026,12,31)),", "&'Input Data'!AB4&" ("&'Input Data'!C4&")","")&IF(('Input Data'!Z5<>"")*('Input Data'!Z5<=DATE(2026,12,31)),", "&'Input Data'!AB5&" ("&'Input Data'!C5&")","")&IF(('Input Data'!Z6<>"")*('Input Data'!Z6<=DATE(2026,12,31)),", "&'Input Data'!AB6&" ("&'Input Data'!C6&")","")&IF(('Input Data'!Z7<>"")*('Input Data'!Z7<=DATE(2026,12,31)),", "&'Input Data'!AB7&" ("&'Input Data'!C7&")","")&IF(('Input Data'!Z8<>"")*('Input Data'!Z8<=DATE(2026,12,31)),", "&'Input Data'!AB8&" ("&'Input Data'!C8&")","")&IF(('Input Data'!Z9<>"")*('Input Data'!Z9<=DATE(2026,12,31)),", "&'Input Data'!AB9&" ("&'Input Data'!C9&")","")&IF(('Input Data'!Z10<>"")*('Input Data'!Z10<=DATE(2026,12,31)),", "&'Input Data'!AB10&" ("&'Input Data'!C10&")","")&IF(('Input Data'!Z11<>"")*('Input Data'!Z11<=DATE(2026,12,31)),", "&'Input Data'!AB11&" ("&'Input Data'!C11&")","")&IF(('Input Data'!Z12<>"")*('Input Data'!Z12<=DATE(2026,12,31)),", "&'Input Data'!AB12&" ("&'Input Data'!C12&")","")&IF(('Input Data'!Z13<>"")*('Input Data'!Z13<=DATE(2026,12,31)),", "&'Input Data'!AB13&" ("&'Input Data'!C13&")","")&IF(('Input Data'!Z14<>"")*('Input Data'!Z14<=DATE(2026,12,31)),", "&'Input Data'!AB14&" ("&'Input Data'!C14&")","")&IF(('Input Data'!Z15<>"")*('Input Data'!Z15<=DATE(2026,12,31)),", "&'Input Data'!AB15&" ("&'Input Data'!C15&")","")&IF(('Input Data'!Z16<>"")*('Input Data'!Z16<=DATE(2026,12,31)),", "&'Input Data'!AB16&" ("&'Input Data'!C16&")","")&IF(('Input Data'!Z17<>"")*('Input Data'!Z17<=DATE(2026,12,31)),", "&'Input Data'!AB17&" ("&'Input Data'!C17&")","")&IF(('Input Data'!Z18<>"")*('Input Data'!Z18<=DATE(2026,12,31)),", "&'Input Data'!AB18&" ("&'Input Data'!C18&")","")&IF(('Input Data'!Z19<>"")*('Input Data'!Z19<=DATE(2026,12,31)),", "&'Input Data'!AB19&" ("&'Input Data'!C19&")","")&IF(('Input Data'!Z20<>"")*('Input Data'!Z20<=DATE(2026,12,31)),", "&'Input Data'!AB20&" ("&'Input Data'!C20&")","")&IF(('Input Data'!Z21<>"")*('Input Data'!Z21<=DATE(2026,12,31)),", "&'Input Data'!AB21&" ("&'Input Data'!C21&")","")&IF(('Input Data'!Z22<>"")*('Input Data'!Z22<=DATE(2026,12,31)),", "&'Input Data'!AB22&" ("&'Input Data'!C22&")","")&IF(('Input Data'!Z23<>"")*('Input Data'!Z23<=DATE(2026,12,31)),", "&'Input Data'!AB23&" ("&'Input Data'!C23&")","")&IF(('Input Data'!Z24<>"")*('Input Data'!Z24<=DATE(2026,12,31)),", "&'Input Data'!AB24&" ("&'Input Data'!C24&")","")&IF(('Input Data'!Z25<>"")*('Input Data'!Z25<=DATE(2026,12,31)),", "&'Input Data'!AB25&" ("&'Input Data'!C25&")","")&IF(('Input Data'!Z26<>"")*('Input Data'!Z26<=DATE(2026,12,31)),", "&'Input Data'!AB26&" ("&'Input Data'!C26&")","")&IF(('Input Data'!Z27<>"")*('Input Data'!Z27<=DATE(2026,12,31)),", "&'Input Data'!AB27&" ("&'Input Data'!C27&")",""),3,999),"—") -> Michael Flegg (1101)
B20: 2027 | C20: =SUMPRODUCT(('Input Data'!Z3:Z27>TODAY())*(YEAR('Input Data'!Z3:Z27)=2027)*('Input Data'!AA3:AA27>0)*'Input Data'!AA3:AA27*'Input Data'!F3:F27) -> 1187255.2 | D20: =IFERROR(C20/(SUMPRODUCT(('Input Data'!Z3:Z27>TODAY())*('Input Data'!AA3:AA27>0)*'Input Data'!AA3:AA27*'Input Data'!F3:F27)),0) -> 0.24445026 | E20: =SUMPRODUCT(('Input Data'!Z3:Z27>TODAY())*(YEAR('Input Data'!Z3:Z27)=2027)*('Input Data'!AA3:AA27>0)*'Input Data'!F3:F27) -> 976.9 | F20: =IFERROR(E20/(SUMPRODUCT(('Input Data'!Z3:Z27>TODAY())*('Input Data'!AA3:AA27>0)*'Input Data'!F3:F27)),0) -> 0.22621804 | G20: =SUMPRODUCT(('Input Data'!Z3:Z27>TODAY())*(YEAR('Input Data'!Z3:Z27)=2027)*('Input Data'!AA3:AA27>0)*1) -> 5 | H20: =IFERROR(MID(IF(('Input Data'!Z3>TODAY())*('Input Data'!AA3>0)*(YEAR('Input Data'!Z3)=2027),", "&'Input Data'!AB3&" ("&'Input Data'!C3&")","")&IF(('Input Data'!Z4>TODAY())*('Input Data'!AA4>0)*(YEAR('Input Data'!Z4)=2027),", "&'Input Data'!AB4&" ("&'Input Data'!C4&")","")&IF(('Input Data'!Z5>TODAY())*('Input Data'!AA5>0)*(YEAR('Input Data'!Z5)=2027),", "&'Input Data'!AB5&" ("&'Input Data'!C5&")","")&IF(('Input Data'!Z6>TODAY())*('Input Data'!AA6>0)*(YEAR('Input Data'!Z6)=2027),", "&'Input Data'!AB6&" ("&'Input Data'!C6&")","")&IF(('Input Data'!Z7>TODAY())*('Input Data'!AA7>0)*(YEAR('Input Data'!Z7)=2027),", "&'Input Data'!AB7&" ("&'Input Data'!C7&")","")&IF(('Input Data'!Z8>TODAY())*('Input Data'!AA8>0)*(YEAR('Input Data'!Z8)=2027),", "&'Input Data'!AB8&" ("&'Input Data'!C8&")","")&IF(('Input Data'!Z9>TODAY())*('Input Data'!AA9>0)*(YEAR('Input Data'!Z9)=2027),", "&'Input Data'!AB9&" ("&'Input Data'!C9&")","")&IF(('Input Data'!Z10>TODAY())*('Input Data'!AA10>0)*(YEAR('Input Data'!Z10)=2027),", "&'Input Data'!AB10&" ("&'Input Data'!C10&")","")&IF(('Input Data'!Z11>TODAY())*('Input Data'!AA11>0)*(YEAR('Input Data'!Z11)=2027),", "&'Input Data'!AB11&" ("&'Input Data'!C11&")","")&IF(('Input Data'!Z12>TODAY())*('Input Data'!AA12>0)*(YEAR('Input Data'!Z12)=2027),", "&'Input Data'!AB12&" ("&'Input Data'!C12&")","")&IF(('Input Data'!Z13>TODAY())*('Input Data'!AA13>0)*(YEAR('Input Data'!Z13)=2027),", "&'Input Data'!AB13&" ("&'Input Data'!C13&")","")&IF(('Input Data'!Z14>TODAY())*('Input Data'!AA14>0)*(YEAR('Input Data'!Z14)=2027),", "&'Input Data'!AB14&" ("&'Input Data'!C14&")","")&IF(('Input Data'!Z15>TODAY())*('Input Data'!AA15>0)*(YEAR('Input Data'!Z15)=2027),", "&'Input Data'!AB15&" ("&'Input Data'!C15&")","")&IF(('Input Data'!Z16>TODAY())*('Input Data'!AA16>0)*(YEAR('Input Data'!Z16)=2027),", "&'Input Data'!AB16&" ("&'Input Data'!C16&")","")&IF(('Input Data'!Z17>TODAY())*('Input Data'!AA17>0)*(YEAR('Input Data'!Z17)=2027),", "&'Input Data'!AB17&" ("&'Input Data'!C17&")","")&IF(('Input Data'!Z18>TODAY())*('Input Data'!AA18>0)*(YEAR('Input Data'!Z18)=2027),", "&'Input Data'!AB18&" ("&'Input Data'!C18&")","")&IF(('Input Data'!Z19>TODAY())*('Input Data'!AA19>0)*(YEAR('Input Data'!Z19)=2027),", "&'Input Data'!AB19&" ("&'Input Data'!C19&")","")&IF(('Input Data'!Z20>TODAY())*('Input Data'!AA20>0)*(YEAR('Input Data'!Z20)=2027),", "&'Input Data'!AB20&" ("&'Input Data'!C20&")","")&IF(('Input Data'!Z21>TODAY())*('Input Data'!AA21>0)*(YEAR('Input Data'!Z21)=2027),", "&'Input Data'!AB21&" ("&'Input Data'!C21&")","")&IF(('Input Data'!Z22>TODAY())*('Input Data'!AA22>0)*(YEAR('Input Data'!Z22)=2027),", "&'Input Data'!AB22&" ("&'Input Data'!C22&")","")&IF(('Input Data'!Z23>TODAY())*('Input Data'!AA23>0)*(YEAR('Input Data'!Z23)=2027),", "&'Input Data'!AB23&" ("&'Input Data'!C23&")","")&IF(('Input Data'!Z24>TODAY())*('Input Data'!AA24>0)*(YEAR('Input Data'!Z24)=2027),", "&'Input Data'!AB24&" ("&'Input Data'!C24&")","")&IF(('Input Data'!Z25>TODAY())*('Input Data'!AA25>0)*(YEAR('Input Data'!Z25)=2027),", "&'Input Data'!AB25&" ("&'Input Data'!C25&")","")&IF(('Input Data'!Z26>TODAY())*('Input Data'!AA26>0)*(YEAR('Input Data'!Z26)=2027),", "&'Input Data'!AB26&" ("&'Input Data'!C26&")","")&IF(('Input Data'!Z27>TODAY())*('Input Data'!AA27>0)*(YEAR('Input Data'!Z27)=2027),", "&'Input Data'!AB27&" ("&'Input Data'!C27&")",""),3,999),"—") -> IPM Residential (301&2), Montgomery Investment (501), Threat Defence (502), Fullcrm (601), Pinpoint Talent (701)
B21: 2028 | C21: =SUMPRODUCT(('Input Data'!Z3:Z27>TODAY())*(YEAR('Input Data'!Z3:Z27)=2028)*('Input Data'!AA3:AA27>0)*'Input Data'!AA3:AA27*'Input Data'!F3:F27) -> 1233906.6 | D21: =IFERROR(C21/(SUMPRODUCT(('Input Data'!Z3:Z27>TODAY())*('Input Data'!AA3:AA27>0)*'Input Data'!AA3:AA27*'Input Data'!F3:F27)),0) -> 0.25405558 | E21: =SUMPRODUCT(('Input Data'!Z3:Z27>TODAY())*(YEAR('Input Data'!Z3:Z27)=2028)*('Input Data'!AA3:AA27>0)*'Input Data'!F3:F27) -> 1171.2 | F21: =IFERROR(E21/(SUMPRODUCT(('Input Data'!Z3:Z27>TODAY())*('Input Data'!AA3:AA27>0)*'Input Data'!F3:F27)),0) -> 0.27121156 | G21: =SUMPRODUCT(('Input Data'!Z3:Z27>TODAY())*(YEAR('Input Data'!Z3:Z27)=2028)*('Input Data'!AA3:AA27>0)*1) -> 7 | H21: =IFERROR(MID(IF(('Input Data'!Z3>TODAY())*('Input Data'!AA3>0)*(YEAR('Input Data'!Z3)=2028),", "&'Input Data'!AB3&" ("&'Input Data'!C3&")","")&IF(('Input Data'!Z4>TODAY())*('Input Data'!AA4>0)*(YEAR('Input Data'!Z4)=2028),", "&'Input Data'!AB4&" ("&'Input Data'!C4&")","")&IF(('Input Data'!Z5>TODAY())*('Input Data'!AA5>0)*(YEAR('Input Data'!Z5)=2028),", "&'Input Data'!AB5&" ("&'Input Data'!C5&")","")&IF(('Input Data'!Z6>TODAY())*('Input Data'!AA6>0)*(YEAR('Input Data'!Z6)=2028),", "&'Input Data'!AB6&" ("&'Input Data'!C6&")","")&IF(('Input Data'!Z7>TODAY())*('Input Data'!AA7>0)*(YEAR('Input Data'!Z7)=2028),", "&'Input Data'!AB7&" ("&'Input Data'!C7&")","")&IF(('Input Data'!Z8>TODAY())*('Input Data'!AA8>0)*(YEAR('Input Data'!Z8)=2028),", "&'Input Data'!AB8&" ("&'Input Data'!C8&")","")&IF(('Input Data'!Z9>TODAY())*('Input Data'!AA9>0)*(YEAR('Input Data'!Z9)=2028),", "&'Input Data'!AB9&" ("&'Input Data'!C9&")","")&IF(('Input Data'!Z10>TODAY())*('Input Data'!AA10>0)*(YEAR('Input Data'!Z10)=2028),", "&'Input Data'!AB10&" ("&'Input Data'!C10&")","")&IF(('Input Data'!Z11>TODAY())*('Input Data'!AA11>0)*(YEAR('Input Data'!Z11)=2028),", "&'Input Data'!AB11&" ("&'Input Data'!C11&")","")&IF(('Input Data'!Z12>TODAY())*('Input Data'!AA12>0)*(YEAR('Input Data'!Z12)=2028),", "&'Input Data'!AB12&" ("&'Input Data'!C12&")","")&IF(('Input Data'!Z13>TODAY())*('Input Data'!AA13>0)*(YEAR('Input Data'!Z13)=2028),", "&'Input Data'!AB13&" ("&'Input Data'!C13&")","")&IF(('Input Data'!Z14>TODAY())*('Input Data'!AA14>0)*(YEAR('Input Data'!Z14)=2028),", "&'Input Data'!AB14&" ("&'Input Data'!C14&")","")&IF(('Input Data'!Z15>TODAY())*('Input Data'!AA15>0)*(YEAR('Input Data'!Z15)=2028),", "&'Input Data'!AB15&" ("&'Input Data'!C15&")","")&IF(('Input Data'!Z16>TODAY())*('Input Data'!AA16>0)*(YEAR('Input Data'!Z16)=2028),", "&'Input Data'!AB16&" ("&'Input Data'!C16&")","")&IF(('Input Data'!Z17>TODAY())*('Input Data'!AA17>0)*(YEAR('Input Data'!Z17)=2028),", "&'Input Data'!AB17&" ("&'Input Data'!C17&")","")&IF(('Input Data'!Z18>TODAY())*('Input Data'!AA18>0)*(YEAR('Input Data'!Z18)=2028),", "&'Input Data'!AB18&" ("&'Input Data'!C18&")","")&IF(('Input Data'!Z19>TODAY())*('Input Data'!AA19>0)*(YEAR('Input Data'!Z19)=2028),", "&'Input Data'!AB19&" ("&'Input Data'!C19&")","")&IF(('Input Data'!Z20>TODAY())*('Input Data'!AA20>0)*(YEAR('Input Data'!Z20)=2028),", "&'Input Data'!AB20&" ("&'Input Data'!C20&")","")&IF(('Input Data'!Z21>TODAY())*('Input Data'!AA21>0)*(YEAR('Input Data'!Z21)=2028),", "&'Input Data'!AB21&" ("&'Input Data'!C21&")","")&IF(('Input Data'!Z22>TODAY())*('Input Data'!AA22>0)*(YEAR('Input Data'!Z22)=2028),", "&'Input Data'!AB22&" ("&'Input Data'!C22&")","")&IF(('Input Data'!Z23>TODAY())*('Input Data'!AA23>0)*(YEAR('Input Data'!Z23)=2028),", "&'Input Data'!AB23&" ("&'Input Data'!C23&")","")&IF(('Input Data'!Z24>TODAY())*('Input Data'!AA24>0)*(YEAR('Input Data'!Z24)=2028),", "&'Input Data'!AB24&" ("&'Input Data'!C24&")","")&IF(('Input Data'!Z25>TODAY())*('Input Data'!AA25>0)*(YEAR('Input Data'!Z25)=2028),", "&'Input Data'!AB25&" ("&'Input Data'!C25&")","")&IF(('Input Data'!Z26>TODAY())*('Input Data'!AA26>0)*(YEAR('Input Data'!Z26)=2028),", "&'Input Data'!AB26&" ("&'Input Data'!C26&")","")&IF(('Input Data'!Z27>TODAY())*('Input Data'!AA27>0)*(YEAR('Input Data'!Z27)=2028),", "&'Input Data'!AB27&" ("&'Input Data'!C27&")",""),3,999),"—") -> PU Prime Trading (103), Princeton Financial Services (WHOLE), Broadridge (303&4), Satellite Office (702), Hilliard & Berry (802), Aitken Investment Mgmt (901), Lewis Woolcott (1102)
B22: 2029 | C22: =SUMPRODUCT(('Input Data'!Z3:Z27>TODAY())*(YEAR('Input Data'!Z3:Z27)=2029)*('Input Data'!AA3:AA27>0)*'Input Data'!AA3:AA27*'Input Data'!F3:F27) -> 1372668 | D22: =IFERROR(C22/(SUMPRODUCT(('Input Data'!Z3:Z27>TODAY())*('Input Data'!AA3:AA27>0)*'Input Data'!AA3:AA27*'Input Data'!F3:F27)),0) -> 0.28262589 | E22: =SUMPRODUCT(('Input Data'!Z3:Z27>TODAY())*(YEAR('Input Data'!Z3:Z27)=2029)*('Input Data'!AA3:AA27>0)*'Input Data'!F3:F27) -> 1284.6 | F22: =IFERROR(E22/(SUMPRODUCT(('Input Data'!Z3:Z27>TODAY())*('Input Data'!AA3:AA27>0)*'Input Data'!F3:F27)),0) -> 0.29747129 | G22: =SUMPRODUCT(('Input Data'!Z3:Z27>TODAY())*(YEAR('Input Data'!Z3:Z27)=2029)*('Input Data'!AA3:AA27>0)*1) -> 7 | H22: =IFERROR(MID(IF(('Input Data'!Z3>TODAY())*('Input Data'!AA3>0)*(YEAR('Input Data'!Z3)=2029),", "&'Input Data'!AB3&" ("&'Input Data'!C3&")","")&IF(('Input Data'!Z4>TODAY())*('Input Data'!AA4>0)*(YEAR('Input Data'!Z4)=2029),", "&'Input Data'!AB4&" ("&'Input Data'!C4&")","")&IF(('Input Data'!Z5>TODAY())*('Input Data'!AA5>0)*(YEAR('Input Data'!Z5)=2029),", "&'Input Data'!AB5&" ("&'Input Data'!C5&")","")&IF(('Input Data'!Z6>TODAY())*('Input Data'!AA6>0)*(YEAR('Input Data'!Z6)=2029),", "&'Input Data'!AB6&" ("&'Input Data'!C6&")","")&IF(('Input Data'!Z7>TODAY())*('Input Data'!AA7>0)*(YEAR('Input Data'!Z7)=2029),", "&'Input Data'!AB7&" ("&'Input Data'!C7&")","")&IF(('Input Data'!Z8>TODAY())*('Input Data'!AA8>0)*(YEAR('Input Data'!Z8)=2029),", "&'Input Data'!AB8&" ("&'Input Data'!C8&")","")&IF(('Input Data'!Z9>TODAY())*('Input Data'!AA9>0)*(YEAR('Input Data'!Z9)=2029),", "&'Input Data'!AB9&" ("&'Input Data'!C9&")","")&IF(('Input Data'!Z10>TODAY())*('Input Data'!AA10>0)*(YEAR('Input Data'!Z10)=2029),", "&'Input Data'!AB10&" ("&'Input Data'!C10&")","")&IF(('Input Data'!Z11>TODAY())*('Input Data'!AA11>0)*(YEAR('Input Data'!Z11)=2029),", "&'Input Data'!AB11&" ("&'Input Data'!C11&")","")&IF(('Input Data'!Z12>TODAY())*('Input Data'!AA12>0)*(YEAR('Input Data'!Z12)=2029),", "&'Input Data'!AB12&" ("&'Input Data'!C12&")","")&IF(('Input Data'!Z13>TODAY())*('Input Data'!AA13>0)*(YEAR('Input Data'!Z13)=2029),", "&'Input Data'!AB13&" ("&'Input Data'!C13&")","")&IF(('Input Data'!Z14>TODAY())*('Input Data'!AA14>0)*(YEAR('Input Data'!Z14)=2029),", "&'Input Data'!AB14&" ("&'Input Data'!C14&")","")&IF(('Input Data'!Z15>TODAY())*('Input Data'!AA15>0)*(YEAR('Input Data'!Z15)=2029),", "&'Input Data'!AB15&" ("&'Input Data'!C15&")","")&IF(('Input Data'!Z16>TODAY())*('Input Data'!AA16>0)*(YEAR('Input Data'!Z16)=2029),", "&'Input Data'!AB16&" ("&'Input Data'!C16&")","")&IF(('Input Data'!Z17>TODAY())*('Input Data'!AA17>0)*(YEAR('Input Data'!Z17)=2029),", "&'Input Data'!AB17&" ("&'Input Data'!C17&")","")&IF(('Input Data'!Z18>TODAY())*('Input Data'!AA18>0)*(YEAR('Input Data'!Z18)=2029),", "&'Input Data'!AB18&" ("&'Input Data'!C18&")","")&IF(('Input Data'!Z19>TODAY())*('Input Data'!AA19>0)*(YEAR('Input Data'!Z19)=2029),", "&'Input Data'!AB19&" ("&'Input Data'!C19&")","")&IF(('Input Data'!Z20>TODAY())*('Input Data'!AA20>0)*(YEAR('Input Data'!Z20)=2029),", "&'Input Data'!AB20&" ("&'Input Data'!C20&")","")&IF(('Input Data'!Z21>TODAY())*('Input Data'!AA21>0)*(YEAR('Input Data'!Z21)=2029),", "&'Input Data'!AB21&" ("&'Input Data'!C21&")","")&IF(('Input Data'!Z22>TODAY())*('Input Data'!AA22>0)*(YEAR('Input Data'!Z22)=2029),", "&'Input Data'!AB22&" ("&'Input Data'!C22&")","")&IF(('Input Data'!Z23>TODAY())*('Input Data'!AA23>0)*(YEAR('Input Data'!Z23)=2029),", "&'Input Data'!AB23&" ("&'Input Data'!C23&")","")&IF(('Input Data'!Z24>TODAY())*('Input Data'!AA24>0)*(YEAR('Input Data'!Z24)=2029),", "&'Input Data'!AB24&" ("&'Input Data'!C24&")","")&IF(('Input Data'!Z25>TODAY())*('Input Data'!AA25>0)*(YEAR('Input Data'!Z25)=2029),", "&'Input Data'!AB25&" ("&'Input Data'!C25&")","")&IF(('Input Data'!Z26>TODAY())*('Input Data'!AA26>0)*(YEAR('Input Data'!Z26)=2029),", "&'Input Data'!AB26&" ("&'Input Data'!C26&")","")&IF(('Input Data'!Z27>TODAY())*('Input Data'!AA27>0)*(YEAR('Input Data'!Z27)=2029),", "&'Input Data'!AB27&" ("&'Input Data'!C27&")",""),3,999),"—") -> Opulent Two Enterprises (LWR GROUND), TJC#1 (104), B-W International (401), Gray Dawes Travel (402), INNOVIS (602), Connectus Services (1001&2), Interfi Systems (1103)
B23: 2030 | C23: =SUMPRODUCT(('Input Data'!Z3:Z27>TODAY())*(YEAR('Input Data'!Z3:Z27)=2030)*('Input Data'!AA3:AA27>0)*'Input Data'!AA3:AA27*'Input Data'!F3:F27) -> 634398.75 | D23: =IFERROR(C23/(SUMPRODUCT(('Input Data'!Z3:Z27>TODAY())*('Input Data'!AA3:AA27>0)*'Input Data'!AA3:AA27*'Input Data'!F3:F27)),0) -> 0.13061972 | E23: =SUMPRODUCT(('Input Data'!Z3:Z27>TODAY())*(YEAR('Input Data'!Z3:Z27)=2030)*('Input Data'!AA3:AA27>0)*'Input Data'!F3:F27) -> 525 | F23: =IFERROR(E23/(SUMPRODUCT(('Input Data'!Z3:Z27>TODAY())*('Input Data'!AA3:AA27>0)*'Input Data'!F3:F27)),0) -> 0.1215728 | G23: =SUMPRODUCT(('Input Data'!Z3:Z27>TODAY())*(YEAR('Input Data'!Z3:Z27)=2030)*('Input Data'!AA3:AA27>0)*1) -> 2 | H23: =IFERROR(MID(IF(('Input Data'!Z3>TODAY())*('Input Data'!AA3>0)*(YEAR('Input Data'!Z3)=2030),", "&'Input Data'!AB3&" ("&'Input Data'!C3&")","")&IF(('Input Data'!Z4>TODAY())*('Input Data'!AA4>0)*(YEAR('Input Data'!Z4)=2030),", "&'Input Data'!AB4&" ("&'Input Data'!C4&")","")&IF(('Input Data'!Z5>TODAY())*('Input Data'!AA5>0)*(YEAR('Input Data'!Z5)=2030),", "&'Input Data'!AB5&" ("&'Input Data'!C5&")","")&IF(('Input Data'!Z6>TODAY())*('Input Data'!AA6>0)*(YEAR('Input Data'!Z6)=2030),", "&'Input Data'!AB6&" ("&'Input Data'!C6&")","")&IF(('Input Data'!Z7>TODAY())*('Input Data'!AA7>0)*(YEAR('Input Data'!Z7)=2030),", "&'Input Data'!AB7&" ("&'Input Data'!C7&")","")&IF(('Input Data'!Z8>TODAY())*('Input Data'!AA8>0)*(YEAR('Input Data'!Z8)=2030),", "&'Input Data'!AB8&" ("&'Input Data'!C8&")","")&IF(('Input Data'!Z9>TODAY())*('Input Data'!AA9>0)*(YEAR('Input Data'!Z9)=2030),", "&'Input Data'!AB9&" ("&'Input Data'!C9&")","")&IF(('Input Data'!Z10>TODAY())*('Input Data'!AA10>0)*(YEAR('Input Data'!Z10)=2030),", "&'Input Data'!AB10&" ("&'Input Data'!C10&")","")&IF(('Input Data'!Z11>TODAY())*('Input Data'!AA11>0)*(YEAR('Input Data'!Z11)=2030),", "&'Input Data'!AB11&" ("&'Input Data'!C11&")","")&IF(('Input Data'!Z12>TODAY())*('Input Data'!AA12>0)*(YEAR('Input Data'!Z12)=2030),", "&'Input Data'!AB12&" ("&'Input Data'!C12&")","")&IF(('Input Data'!Z13>TODAY())*('Input Data'!AA13>0)*(YEAR('Input Data'!Z13)=2030),", "&'Input Data'!AB13&" ("&'Input Data'!C13&")","")&IF(('Input Data'!Z14>TODAY())*('Input Data'!AA14>0)*(YEAR('Input Data'!Z14)=2030),", "&'Input Data'!AB14&" ("&'Input Data'!C14&")","")&IF(('Input Data'!Z15>TODAY())*('Input Data'!AA15>0)*(YEAR('Input Data'!Z15)=2030),", "&'Input Data'!AB15&" ("&'Input Data'!C15&")","")&IF(('Input Data'!Z16>TODAY())*('Input Data'!AA16>0)*(YEAR('Input Data'!Z16)=2030),", "&'Input Data'!AB16&" ("&'Input Data'!C16&")","")&IF(('Input Data'!Z17>TODAY())*('Input Data'!AA17>0)*(YEAR('Input Data'!Z17)=2030),", "&'Input Data'!AB17&" ("&'Input Data'!C17&")","")&IF(('Input Data'!Z18>TODAY())*('Input Data'!AA18>0)*(YEAR('Input Data'!Z18)=2030),", "&'Input Data'!AB18&" ("&'Input Data'!C18&")","")&IF(('Input Data'!Z19>TODAY())*('Input Data'!AA19>0)*(YEAR('Input Data'!Z19)=2030),", "&'Input Data'!AB19&" ("&'Input Data'!C19&")","")&IF(('Input Data'!Z20>TODAY())*('Input Data'!AA20>0)*(YEAR('Input Data'!Z20)=2030),", "&'Input Data'!AB20&" ("&'Input Data'!C20&")","")&IF(('Input Data'!Z21>TODAY())*('Input Data'!AA21>0)*(YEAR('Input Data'!Z21)=2030),", "&'Input Data'!AB21&" ("&'Input Data'!C21&")","")&IF(('Input Data'!Z22>TODAY())*('Input Data'!AA22>0)*(YEAR('Input Data'!Z22)=2030),", "&'Input Data'!AB22&" ("&'Input Data'!C22&")","")&IF(('Input Data'!Z23>TODAY())*('Input Data'!AA23>0)*(YEAR('Input Data'!Z23)=2030),", "&'Input Data'!AB23&" ("&'Input Data'!C23&")","")&IF(('Input Data'!Z24>TODAY())*('Input Data'!AA24>0)*(YEAR('Input Data'!Z24)=2030),", "&'Input Data'!AB24&" ("&'Input Data'!C24&")","")&IF(('Input Data'!Z25>TODAY())*('Input Data'!AA25>0)*(YEAR('Input Data'!Z25)=2030),", "&'Input Data'!AB25&" ("&'Input Data'!C25&")","")&IF(('Input Data'!Z26>TODAY())*('Input Data'!AA26>0)*(YEAR('Input Data'!Z26)=2030),", "&'Input Data'!AB26&" ("&'Input Data'!C26&")","")&IF(('Input Data'!Z27>TODAY())*('Input Data'!AA27>0)*(YEAR('Input Data'!Z27)=2030),", "&'Input Data'!AB27&" ("&'Input Data'!C27&")",""),3,999),"—") -> Arkance Australia (801), Capital E Marketing (902&3)
B24: 2031+ | C24: =SUMPRODUCT(('Input Data'!Z3:Z27>TODAY())*(YEAR('Input Data'!Z3:Z27)>=2031)*('Input Data'!AA3:AA27>0)*'Input Data'!AA3:AA27*'Input Data'!F3:F27) -> 343200.12 | D24: =IFERROR(C24/(SUMPRODUCT(('Input Data'!Z3:Z27>TODAY())*('Input Data'!AA3:AA27>0)*'Input Data'!AA3:AA27*'Input Data'!F3:F27)),0) -> 0.070663291 | E24: =SUMPRODUCT(('Input Data'!Z3:Z27>TODAY())*(YEAR('Input Data'!Z3:Z27)>=2031)*('Input Data'!AA3:AA27>0)*'Input Data'!F3:F27) -> 298.3 | F24: =IFERROR(E24/(SUMPRODUCT(('Input Data'!Z3:Z27>TODAY())*('Input Data'!AA3:AA27>0)*'Input Data'!F3:F27)),0) -> 0.06907651 | G24: =SUMPRODUCT(('Input Data'!Z3:Z27>TODAY())*(YEAR('Input Data'!Z3:Z27)>=2031)*('Input Data'!AA3:AA27>0)*1) -> 1 | H24: =IFERROR(MID(IF(('Input Data'!Z3>TODAY())*('Input Data'!AA3>0)*(YEAR('Input Data'!Z3)>=2031),", "&'Input Data'!AB3&" ("&'Input Data'!C3&")","")&IF(('Input Data'!Z4>TODAY())*('Input Data'!AA4>0)*(YEAR('Input Data'!Z4)>=2031),", "&'Input Data'!AB4&" ("&'Input Data'!C4&")","")&IF(('Input Data'!Z5>TODAY())*('Input Data'!AA5>0)*(YEAR('Input Data'!Z5)>=2031),", "&'Input Data'!AB5&" ("&'Input Data'!C5&")","")&IF(('Input Data'!Z6>TODAY())*('Input Data'!AA6>0)*(YEAR('Input Data'!Z6)>=2031),", "&'Input Data'!AB6&" ("&'Input Data'!C6&")","")&IF(('Input Data'!Z7>TODAY())*('Input Data'!AA7>0)*(YEAR('Input Data'!Z7)>=2031),", "&'Input Data'!AB7&" ("&'Input Data'!C7&")","")&IF(('Input Data'!Z8>TODAY())*('Input Data'!AA8>0)*(YEAR('Input Data'!Z8)>=2031),", "&'Input Data'!AB8&" ("&'Input Data'!C8&")","")&IF(('Input Data'!Z9>TODAY())*('Input Data'!AA9>0)*(YEAR('Input Data'!Z9)>=2031),", "&'Input Data'!AB9&" ("&'Input Data'!C9&")","")&IF(('Input Data'!Z10>TODAY())*('Input Data'!AA10>0)*(YEAR('Input Data'!Z10)>=2031),", "&'Input Data'!AB10&" ("&'Input Data'!C10&")","")&IF(('Input Data'!Z11>TODAY())*('Input Data'!AA11>0)*(YEAR('Input Data'!Z11)>=2031),", "&'Input Data'!AB11&" ("&'Input Data'!C11&")","")&IF(('Input Data'!Z12>TODAY())*('Input Data'!AA12>0)*(YEAR('Input Data'!Z12)>=2031),", "&'Input Data'!AB12&" ("&'Input Data'!C12&")","")&IF(('Input Data'!Z13>TODAY())*('Input Data'!AA13>0)*(YEAR('Input Data'!Z13)>=2031),", "&'Input Data'!AB13&" ("&'Input Data'!C13&")","")&IF(('Input Data'!Z14>TODAY())*('Input Data'!AA14>0)*(YEAR('Input Data'!Z14)>=2031),", "&'Input Data'!AB14&" ("&'Input Data'!C14&")","")&IF(('Input Data'!Z15>TODAY())*('Input Data'!AA15>0)*(YEAR('Input Data'!Z15)>=2031),", "&'Input Data'!AB15&" ("&'Input Data'!C15&")","")&IF(('Input Data'!Z16>TODAY())*('Input Data'!AA16>0)*(YEAR('Input Data'!Z16)>=2031),", "&'Input Data'!AB16&" ("&'Input Data'!C16&")","")&IF(('Input Data'!Z17>TODAY())*('Input Data'!AA17>0)*(YEAR('Input Data'!Z17)>=2031),", "&'Input Data'!AB17&" ("&'Input Data'!C17&")","")&IF(('Input Data'!Z18>TODAY())*('Input Data'!AA18>0)*(YEAR('Input Data'!Z18)>=2031),", "&'Input Data'!AB18&" ("&'Input Data'!C18&")","")&IF(('Input Data'!Z19>TODAY())*('Input Data'!AA19>0)*(YEAR('Input Data'!Z19)>=2031),", "&'Input Data'!AB19&" ("&'Input Data'!C19&")","")&IF(('Input Data'!Z20>TODAY())*('Input Data'!AA20>0)*(YEAR('Input Data'!Z20)>=2031),", "&'Input Data'!AB20&" ("&'Input Data'!C20&")","")&IF(('Input Data'!Z21>TODAY())*('Input Data'!AA21>0)*(YEAR('Input Data'!Z21)>=2031),", "&'Input Data'!AB21&" ("&'Input Data'!C21&")","")&IF(('Input Data'!Z22>TODAY())*('Input Data'!AA22>0)*(YEAR('Input Data'!Z22)>=2031),", "&'Input Data'!AB22&" ("&'Input Data'!C22&")","")&IF(('Input Data'!Z23>TODAY())*('Input Data'!AA23>0)*(YEAR('Input Data'!Z23)>=2031),", "&'Input Data'!AB23&" ("&'Input Data'!C23&")","")&IF(('Input Data'!Z24>TODAY())*('Input Data'!AA24>0)*(YEAR('Input Data'!Z24)>=2031),", "&'Input Data'!AB24&" ("&'Input Data'!C24&")","")&IF(('Input Data'!Z25>TODAY())*('Input Data'!AA25>0)*(YEAR('Input Data'!Z25)>=2031),", "&'Input Data'!AB25&" ("&'Input Data'!C25&")","")&IF(('Input Data'!Z26>TODAY())*('Input Data'!AA26>0)*(YEAR('Input Data'!Z26)>=2031),", "&'Input Data'!AB26&" ("&'Input Data'!C26&")","")&IF(('Input Data'!Z27>TODAY())*('Input Data'!AA27>0)*(YEAR('Input Data'!Z27)>=2031),", "&'Input Data'!AB27&" ("&'Input Data'!C27&")",""),3,999),"—") -> Recoverie (GROUND)
B25: TOTAL (Occupied) | C25: =SUMPRODUCT(('Input Data'!Z3:Z27>TODAY())*('Input Data'!AA3:AA27>0)*'Input Data'!AA3:AA27*'Input Data'!F3:F27) -> 4856837.4 | D25: =SUM(C19:C24) -> 4856837.4 | E25: =SUMPRODUCT(('Input Data'!Z3:Z27>TODAY())*('Input Data'!AA3:AA27>0)*'Input Data'!F3:F27) -> 4318.4 | F25: =SUM(E19:E24) -> 4318.4 | G25: =100% -> 1 | H25: 23 | I25: =SUM(G19:G24) -> 23
B27: PASSING RENT vs MARKET RENT ANALYSIS — 'Market Rents 26-27'
B28: Suite | C28: Tenant | E28: NLA | F28: Passing PSM | G28: Market PSM | H28: Var ($) | I28: Var (%) | J28: Position
B29: ='Input Data'!C3 -> LWR GROUND | C29: ='Input Data'!D3 -> OPULENT TWO ENTERPRISES | E29: ='Input Data'!F3 -> 151.2 | F29: ='Input Data'!J3 -> 1002.01 | G29: ='Input Data'!S3 -> 930 | H29: =F29-G29 -> 72.01 | I29: =IFERROR((F29-G29)/G29,0) -> 0.077430108 | J29: =IF(I29>0.05,"▲ Above Market",IF(I29<-0.05,"▼ Below Market","≈ At Market")) -> ▲ Above Market
B30: ='Input Data'!C4 -> GROUND | C30: ='Input Data'!D4 -> RCVRI MARTIN PLACE PTY LTD | E30: ='Input Data'!F4 -> 298.3 | F30: ='Input Data'!J4 -> 1150.52 | G30: ='Input Data'!S4 -> 1100 | H30: =F30-G30 -> 50.52 | I30: =IFERROR((F30-G30)/G30,0) -> 0.045927273 | J30: =IF(I30>0.05,"▲ Above Market",IF(I30<-0.05,"▼ Below Market","≈ At Market")) -> ≈ At Market
B31: ='Input Data'!C5 -> 101&2 | C31: ='Input Data'!D5 -> VACANT | E31: ='Input Data'!F5 -> 162.4 | F31: ='Input Data'!J5 -> 0 | G31: ='Input Data'!S5 -> 1115 | H31: =F31-G31 -> -1115 | I31: =IFERROR((F31-G31)/G31,0) -> -1 | J31: =IF(I31>0.05,"▲ Above Market",IF(I31<-0.05,"▼ Below Market","≈ At Market")) -> ▼ Below Market
B32: ='Input Data'!C6 -> 103 | C32: ='Input Data'!D6 -> PU PRIME TRADING PTY LTD | E32: ='Input Data'!F6 -> 96.3 | F32: ='Input Data'!J6 -> 1021.99 | G32: ='Input Data'!S6 -> 960 | H32: =F32-G32 -> 61.99 | I32: =IFERROR((F32-G32)/G32,0) -> 0.064572917 | J32: =IF(I32>0.05,"▲ Above Market",IF(I32<-0.05,"▼ Below Market","≈ At Market")) -> ▲ Above Market
B33: ='Input Data'!C7 -> 104 | C33: ='Input Data'!D7 -> TJC#1 PTY LTD | E33: ='Input Data'!F7 -> 98.1 | F33: ='Input Data'!J7 -> 973.44 | G33: ='Input Data'!S7 -> 960 | H33: =F33-G33 -> 13.44 | I33: =IFERROR((F33-G33)/G33,0) -> 0.014 | J33: =IF(I33>0.05,"▲ Above Market",IF(I33<-0.05,"▼ Below Market","≈ At Market")) -> ≈ At Market
B34: ='Input Data'!C8 -> WHOLE | C34: ='Input Data'!D8 -> PRINCETON FINANCIAL SERVICES | E34: ='Input Data'!F8 -> 393.2 | F34: ='Input Data'!J8 -> 1081.6 | G34: ='Input Data'!S8 -> 1095 | H34: =F34-G34 -> -13.4 | I34: =IFERROR((F34-G34)/G34,0) -> -0.012237443 | J34: =IF(I34>0.05,"▲ Above Market",IF(I34<-0.05,"▼ Below Market","≈ At Market")) -> ≈ At Market
B35: ='Input Data'!C9 -> 301&2 | C35: ='Input Data'!D9 -> IPM RESIDENTIAL PTY LTD | E35: ='Input Data'!F9 -> 164.2 | F35: ='Input Data'!J9 -> 1216.58 | G35: ='Input Data'!S9 -> 1135 | H35: =F35-G35 -> 81.58 | I35: =IFERROR((F35-G35)/G35,0) -> 0.071876652 | J35: =IF(I35>0.05,"▲ Above Market",IF(I35<-0.05,"▼ Below Market","≈ At Market")) -> ▲ Above Market
B36: ='Input Data'!C10 -> 303&4 | C36: ='Input Data'!D10 -> BROADRIDGE (AUSTRALIA) PTY LTD | E36: ='Input Data'!F10 -> 193.4 | F36: ='Input Data'!J10 -> 933.75 | G36: ='Input Data'!S10 -> 920 | H36: =F36-G36 -> 13.75 | I36: =IFERROR((F36-G36)/G36,0) -> 0.014945652 | J36: =IF(I36>0.05,"▲ Above Market",IF(I36<-0.05,"▼ Below Market","≈ At Market")) -> ≈ At Market
