Workbook

Sheet Cover
B3: GOLDBERG FAMILY OFFICE
B9: 1 Elizabeth Plaza
B16: Asset Summary — Tenancy Schedule
B18: As at 29 June 2026
B27: — | C27: Prepared by jake goldberg

Sheet Last Updated
A1: 1 ELIZABETH PLAZA, NORTH SYDNEY — TRACKER VERSION CONTROL
A2: Update Input Data tab each month from the tenancy schedule. All other tabs recalculate automatically.
B4: CURRENT TRACKER STATUS
B5: Property | D5: 1 Elizabeth Plaza, North Sydney
B6: Current As At | D6: 46295
B7: Total NLA | D7: 8940.9
B8: Occupancy | D8: ='Input Data'!B53 -> 0
B9: Vacancy | D9: ='Input Data'!B54 -> 0
B10: WALE by NLA | D10: ='Input Data'!V53 -> 0
B11: Gross Income PA | D11: ='Input Data'!K53 -> 0
B12: Occupied Suites | D12: 17 | 4 Vacant
B13: Car Parks | D13: Monthly + individual licences
B14: Last Updated By
B15: Next Update Due
B16: Notes / Changes
B18: UPDATE LOG
B19: Date Updated | C19: Updated By | D19: As At Date | E19: Occupancy | F19: WALE (NLA) | G19: Key Changes
B20: 46142 | D20: 30/04/2026 | E20: 79.74% | F20: ~4.0 yrs | G20: Initial build from April 2026 tenancy schedule
B21: 46296 | C21: Jake | D21: 30/09/2026 | E21: ='Input Data'!K26 -> 0.91197754 | F21: ='Input Data'!V25 -> 5.9575633 | G21: Refreshed from Sept26 TS (dated 01/10/26): FIXED reviews applied for Sydney Smiletree, Keeping Company, Elekta, Can Too Foundation, Pitt & Sherry, Vanderlande (all PSM ups); outgoings/cleaning refreshed across most tenants. Asterx (0503) lease dates corrected (01/07/24–30/06/29, was 01/06/24–31/05/29) plus abatement/car park/cleaning/outgoings now confirmed. IMPORTANT correction: Smile Partners (0902) and Hulsbosch Design (1201) had swapped NLA/financials in this file — 0902 is actually 344.5 sqm, 1201 is actually 251 sqm — now fixed, cross-checked against the Fitout Costs register. Sungrow L7 (0701/0702) combined rent reset to $925,326 pa total, an 82% jump — flagged in row notes for verification. Caladas Constructions renamed to correct spelling 'Caldas', lease start corrected to 01/07/26. Luxasia (1101) entered as occupied per Jake's instruction: outgoings $9,728.72 pa, cleaning $4,015.80 pa, fitout contribution $369,812.50 (added to Fitout Costs register), abatement $192,787.50 over term (Yr1-3 $25,705 pa now reflected; Yr4-5 $57,836.25 pa needs manual update at the Yr4 anniversary). New ROOF1 (Pipe Networks/Vocus) comms licence ($2,500 pa) identified on the TS but NOT added to this table (zero NLA, would need a new row/range change) — flagged for Jake's decision on where to capture it. Note: TS's own vacancy count still shows 1101 as vacant (lease not yet in the PM system) — this file now diverges from that by design. Cross-tab sweep: corrected the same Smile Partners/Hulsbosch swap in the Leasing Activity log; moved Luxasia out of the 'vacant suites' sections in Expiry Profile/Leases into its proper occupied row; updated Make Good Obligations, Dashboard (critical dates, suite count, header), Market Rents (hardcoded NLA), Leasing Fees (vacancy register — removed 6.01/11.01/11.02, now leased) and Stack Plan (roof tenant name corrected to Pipe Networks/Vocus, portfolio summary refreshed) so all tabs now agree with Input Data.
B39: MONTHLY UPDATE CHECKLIST
B40: 1 | C40: Download tenancy schedule from property management system (Strata/SHP2)
B41: 2 | C41: Update Input Data — check rent, dates, PSM, abatement, outgoings per suite
B42: 3 | C42: Update Market Rents section in Dashboard if market has moved
B43: 4 | C43: Check Dashboard KPIs reconcile with tenancy schedule totals
B44: 5 | C44: Update Leasing Activity tab with new deals, HOAs, renewals
B45: 6 | C45: Update Fitout Costs with any new capex approved or completed
B46: 7 | C46: Update Leasing Fees with current vacancy and asking rents
B47: 8 | C47: Update Rental Analysis for any new deals being analysed
B48: 9 | C48: Record update in Log above — date, occupancy, WALE, key changes
B49: 10 | C49: Save as 1ElizabethPlaza_[MonthYY].xlsx

Sheet Input Data
A1: 1 ELIZABETH PLAZA, NORTH SYDNEY — TENANCY SCHEDULE INPUT | As at 30.9.2026
A2: Suite ID | B2: Floor | C2: Suite # | D2: Tenant Name | E2: Trading Name | F2: NLA (sqm) | G2: Lease Start | H2: Lease Expiry | I2: Term (Yrs) | J2: Face PSM ($) | K2: Office Rent PA ($) | L2: Abatement PA ($) | M2: Outgoings PA ($) | N2: Cleaning PA ($) | O2: Car Park Rent PA ($) | P2: Car Park Levy PA ($) | Q2: Net Effective PA ($) | R2: Car Parks | S2: Review Type | T2: Next Review | U2: Lease Type | V2: WALE (yrs) | W2: Wtd NLA | X2: Market PSM ($) | Y2: Var to Mkt ($) | Z2: Var to Mkt (%) | AA2: Bank Guarantee ($) | AB2: Notes | AC2: Status | AD2: Expiry Source (Enter Here) | AE2: PSM Source | AF2: Display Name
A3: 0301 | B3: L03 | C3: 3.01 | D3: Sydney Smiletree Pty Ltd | E3: The Trustee for Sydney Smiletree Unit Trust | F3: 107.7 | G3: 44013 | H3: 47118 | I3: 8.5 | J3: 1395.94 | K3: =IF(J3>0,J3*F3,0) -> 150342.74 | L3: 0 | M3: 9156 | N3: 0 | O3: 9032.64 | P3: 3030 | Q3: =K3+L3+M3+N3+O3+P3 -> 171561.38 | R3: 1 | S3: FIXED 4% | T3: 46569 | U3: Net | V3: =IFERROR(MAX((H3-TODAY())/365.25,0),0) -> 2.2094456 | W3: =F3*V3 -> 237.95729 | X3: 950 | Y3: =IF(J3>0,J3-X3,0) -> 445.94 | Z3: =IFERROR(IF(J3>0,(J3-X3)/X3,0),0) -> 0.46941053 | AA3: 86814.00 | AB3: Option: 5 yrs. BG: $86,814. Car Space 16. | AC3: =IF(AD3="","VACANT",IF(AD3<TODAY(),"EXPIRED","ACTIVE")) -> ACTIVE | AD3: 47118 | AE3: 1395.94 | AF3: Sydney Smiletree
A4: 0302 | B4: L03 | C4: 3.02 | D4: Fitness First Australia Pty Limited | E4: Fitness First Australia Pty Limited | F4: 795.5 | G4: 44378 | H4: 48029 | I4: 10 | J4: 855.7 | K4: =IF(J4>0,J4*F4,0) -> 680709.35 | L4: 0 | M4: 0 | N4: 0 | O4: 0 | P4: 0 | Q4: =K4+L4+M4+N4+O4+P4 -> 680709.35 | R4: 0 | S4: FIXED 4% | T4: 46204 | U4: Gross | V4: =IFERROR(MAX((H4-TODAY())/365.25,0),0) -> 4.7036277 | W4: =F4*V4 -> 3741.7358 | X4: 870 | Y4: =IF(J4>0,J4-X4,0) -> -14.3 | Z4: =IFERROR(IF(J4>0,(J4-X4)/X4,0),0) -> -0.016436782 | AA4: 300000.40 | AB4: Gross lease - Nil outgoings. Includes direct AC recovery $108.09 psm. Option: 5 yrs (01/07/26-30/06/31). | AC4: =IF(AD4="","VACANT",IF(AD4<TODAY(),"EXPIRED","ACTIVE")) -> ACTIVE | AD4: 48029 | AE4: 855.7 | AF4: Fitness First (L3)
A5: 0401 | B5: L04 | C5: 4.01 | D5: Fitness First Australia Pty Limited | E5: Fitness First Australia Pty Limited | F5: 1047 | G5: 44378 | H5: 48029 | I5: 10 | J5: 855.7 | K5: =IF(J5>0,J5*F5,0) -> 895917.9 | L5: 0 | M5: 0 | N5: 0 | O5: 10160.4 | P5: 0 | Q5: =K5+L5+M5+N5+O5+P5 -> 906078.3 | R5: 1 | S5: FIXED 4% | T5: 46204 | U5: Gross | V5: =IFERROR(MAX((H5-TODAY())/365.25,0),0) -> 4.7036277 | W5: =F5*V5 -> 4924.6982 | X5: 870 | Y5: =IF(J5>0,J5-X5,0) -> -14.3 | Z5: =IFERROR(IF(J5>0,(J5-X5)/X5,0),0) -> -0.016436782 | AA5: 300000.40 | AB5: Gross lease - Nil outgoings. 1 car space. | AC5: =IF(AD5="","VACANT",IF(AD5<TODAY(),"EXPIRED","ACTIVE")) -> ACTIVE | AD5: 48029 | AE5: 855.7 | AF5: Fitness First (L4)
A6: 0501 | B6: L05 | C6: 5.01 | D6: Fitness First Australia Pty Limited | E6: Fitness First North Sydney | F6: 437.1 | G6: 44378 | H6: 48029 | I6: 10 | J6: 855.7 | K6: =IF(J6>0,J6*F6,0) -> 374026.47 | L6: 0 | M6: 0 | N6: 0 | O6: 0 | P6: 3030 | Q6: =K6+L6+M6+N6+O6+P6 -> 377056.47 | R6: 0 | S6: FIXED 4% | T6: 46204 | U6: Gross | V6: =IFERROR(MAX((H6-TODAY())/365.25,0),0) -> 4.7036277 | W6: =F6*V6 -> 2055.9556 | X6: 870 | Y6: =IF(J6>0,J6-X6,0) -> -14.3 | Z6: =IFERROR(IF(J6>0,(J6-X6)/X6,0),0) -> -0.016436782 | AA6: 300000.40 | AB6: Gross lease - Nil outgoings. Car park levy only. | AC6: =IF(AD6="","VACANT",IF(AD6<TODAY(),"EXPIRED","ACTIVE")) -> ACTIVE | AD6: 48029 | AE6: 855.7 | AF6: Fitness First N. Sydney
A7: 0503 | B7: L05 | C7: 5.03 | D7: Asterx Pty Ltd | E7: Asterx Pty Ltd (MediRecords) | F7: 229.8 | G7: 45474 | H7: 47299 | I7: 5 | J7: 985.53 | K7: =IF(J7>0,J7*F7,0) -> 226474.79 | L7: -46511.52 | M7: 10521.96 | N7: 3805.44 | O7: 7712.76 | P7: 3030 | Q7: =K7+L7+M7+N7+O7+P7 -> 205033.43 | R7: 1 | S7: FIXED 3.5% | T7: 46569 | U7: Semi-Gross | V7: =IFERROR(MAX((H7-TODAY())/365.25,0),0) -> 2.7049966 | W7: =F7*V7 -> 621.60821 | X7: 950 | Y7: =IF(J7>0,J7-X7,0) -> 35.53 | Z7: =IFERROR(IF(J7>0,(J7-X7)/X7,0),0) -> 0.0374 | AA7: 135234.00 | AB7: Semi-gross base year FY24. BG: $135,234. 1 car space. Lease start/expiry corrected to 01/07/24–30/06/29 per Sept26 TS (previously recorded as 01/06/24–31/05/29). Abatement, car park rent, cleaning and outgoings all confirmed/updated per Sept26 TS. | AC7: =IF(AD7="","VACANT",IF(AD7<TODAY(),"EXPIRED","ACTIVE")) -> ACTIVE | AD7: 47299 | AE7: 985.53 | AF7: Asterx (MediRecords)
A8: 0504 | B8: L05 | C8: 5.04 | D8: Auctionsplus Pty Ltd | E8: Auctionsplus Pty Ltd | F8: 413.5 | G8: 45352 | H8: 47177 | I8: 5 | J8: 1005.89 | K8: =IF(J8>0,J8*F8,0) -> 415935.52 | L8: -104594.82 | M8: 40068.6 | N8: 6847.56 | O8: 5381.04 | P8: 3030 | Q8: =K8+L8+M8+N8+O8+P8 -> 366667.89 | R8: 1 | S8: FIXED 4% | T8: 46447 | U8: Semi-Gross | V8: =IFERROR(MAX((H8-TODAY())/365.25,0),0) -> 2.3709788 | W8: =F8*V8 -> 980.39973 | X8: 990 | Y8: =IF(J8>0,J8-X8,0) -> 15.89 | Z8: =IFERROR(IF(J8>0,(J8-X8)/X8,0),0) -> 0.016050505 | AA8: 199187.44 | AB8: Semi-gross base year FY24 2.4%. BG equiv $199,187 incl GST. Incentive: fitout contribution $672,971. | AC8: =IF(AD8="","VACANT",IF(AD8<TODAY(),"EXPIRED","ACTIVE")) -> ACTIVE | AD8: 47177 | AE8: 1005.89 | AF8: Auctionsplus
A9: 0602 | B9: L06 | C9: 6.02 | D9: Sungrow Australia Group | E9: Sungrow Australia Group Pty Ltd | F9: 451.7 | G9: 45762 | H9: 47375 | I9: 4.4 | J9: 954.5 | K9: =IF(J9>0,J9*F9,0) -> 431147.65 | L9: -211720.82 | M9: 45907.32 | N9: 7480.2 | O9: 7416 | P9: 3030 | Q9: =K9+L9+M9+N9+O9+P9 -> 283260.35 | R9: 1 | S9: FIXED 3.75% | T9: 46492 | U9: Semi-Gross | V9: =IFERROR(MAX((H9-TODAY())/365.25,0),0) -> 2.9130732 | W9: =F9*V9 -> 1315.8352 | X9: 955 | Y9: =IF(J9>0,J9-X9,0) -> -0.5 | Z9: =IFERROR(IF(J9>0,(J9-X9)/X9,0),0) -> -0.00052356021 | AA9: 291050.49 | AB9: BG: $291,050 (6 mths last yr gross rent). Incentive: 50% of rent as abatement. Make Good: $200 psm. | AC9: =IF(AD9="","VACANT",IF(AD9<TODAY(),"EXPIRED","ACTIVE")) -> ACTIVE | AD9: 47375 | AE9: 954.5 | AF9: Sungrow (L6)
A10: 0603 | B10: L06 | C10: 6.03 | D10: Keeping Company Pty Ltd | E10: Keeping Company Pty Ltd | F10: 189.4 | G10: 44713 | H10: 46538 | I10: 5 | J10: 1055.72 | K10: =IF(J10>0,J10*F10,0) -> 199953.37 | L10: -23525.37 | M10: 19249.32 | N10: 3136.44 | O10: 14183.28 | P10: 6060 | Q10: =K10+L10+M10+N10+O10+P10 -> 219057.04 | R10: 2 | S10: FIXED 3.5% | T10: 46539 | U10: Semi-Gross | V10: =IFERROR(MAX((H10-TODAY())/365.25,0),0) -> 0.62149213 | W10: =F10*V10 -> 117.71061 | X10: 990 | Y10: =IF(J10>0,J10-X10,0) -> 65.72 | Z10: =IFERROR(IF(J10>0,(J10-X10)/X10,0),0) -> 0.066383838 | AA10: 110738.92 | AB10: 2 car spaces. BG: $110,739. Incentive: fitout $177,810 + abatement. Base year FY2021. | AC10: =IF(AD10="","VACANT",IF(AD10<TODAY(),"EXPIRED","ACTIVE")) -> ACTIVE | AD10: 46538 | AE10: 1055.72 | AF10: Keeping Company
A11: 0604 | B11: L06 | C11: 6.04 | D11: Elekta Pty Limited | E11: Elekta Pty Limited | F11: 267.9 | G11: 45870 | H11: 48426 | I11: 7 | J11: 954.5 | K11: =IF(J11>0,J11*F11,0) -> 255710.55 | L11: -98587.2 | M11: 6957 | N11: 4436.4 | O11: 3030 | P11: 0 | Q11: =K11+L11+M11+N11+O11+P11 -> 171546.75 | R11: 1 | S11: FIXED (3.75%) | T11: 46600 | U11: Semi-Gross | V11: =IFERROR(MAX((H11-TODAY())/365.25,0),0) -> 5.7905544 | W11: =F11*V11 -> 1551.2895 | X11: 955 | Y11: =IF(J11>0,J11-X11,0) -> -0.5 | Z11: =IFERROR(IF(J11>0,(J11-X11)/X11,0),0) -> -0.00052356021 | AA11: 210969.39 | AB11: New lease 01/08/25. BG: $210,969. Abatement: $2,576 psm over term. Outgoings 2.95% base FY2025. | AC11: =IF(AD11="","VACANT",IF(AD11<TODAY(),"EXPIRED","ACTIVE")) -> ACTIVE | AD11: 48426 | AE11: 954.5 | AF11: Elekta
A12: 0701 | B12: L07 | C12: 7.01 | D12: Sungrow Australia Group | E12: Sungrow Australia Group Pty Ltd | F12: 484.1 | G12: 45184 | H12: 47375 | I12: 6 | J12: 1911.44 | K12: =IF(J12>0,J12*F12,0) -> 925328.1 | L12: -319000.32 | M12: 49200.48 | N12: 14069.4 | O12: 18074.64 | P12: 6060 | Q12: =K12+L12+M12+N12+O12+P12 -> 693732.3 | R12: 2 | S12: FIXED 3.75% | T12: 46645 | U12: Semi-Gross | V12: =IFERROR(MAX((H12-TODAY())/365.25,0),0) -> 2.9130732 | W12: =F12*V12 -> 1410.2188 | X12: 1020 | Y12: =IF(J12>0,J12-X12,0) -> 891.44 | Z12: =IFERROR(IF(J12>0,(J12-X12)/X12,0),0) -> 0.87396078 | AA12: 536314.24 | AB12: Tandem bays x2. BG: $536,314. Base year FY2021 9.41%. Sept26 TS shows office rent reset to a combined total of $925,326 pa across 7.01+7.02 (849.6 sqm) — PSM above is a blended rate ($925,326/484.1 sqm) to keep this in the existing K=PSM×NLA formula; not a genuine per-sqm market rate, so Var to Mkt for this row is not meaningful. This is an 82% jump on the prior $508k combined rent — flagging for verification against the lease before relying on it. | AC12: =IF(AD12="","VACANT",IF(AD12<TODAY(),"EXPIRED","ACTIVE")) -> ACTIVE | AD12: 47375 | AE12: 1911.44 | AF12: Sungrow (L7 Main)
A13: 0702 | B13: L07 | C13: 7.02 | D13: Sungrow Australia Group | E13: Additional Space (Sungrow) | F13: 365.5 | G13: 45184 | H13: 47375 | I13: 6 | J13: 0 | K13: =IF(J13>0,J13*F13,0) -> 0 | L13: 0 | M13: 37146.72 | N13: 0 | O13: 0 | P13: 0 | Q13: =K13+L13+M13+N13+O13+P13 -> 37146.72 | R13: 0 | S13: FIXED 3.75% | T13: 46645 | U13: Semi-Gross | V13: =IFERROR(MAX((H13-TODAY())/365.25,0),0) -> 2.9130732 | W13: =F13*V13 -> 1064.7283 | X13: 1020 | Y13: =IF(J13>0,J13-X13,0) -> 0 | Z13: =IFERROR(IF(J13>0,(J13-X13)/X13,0),0) -> 0 | AA13: 0 | AB13: Additional space - office rent included in Suite 7.01 totals (same lease). Sept26 TS now shows a separate Outgoings Recoverable charge of $37,146.72 pa billed against this suite. | AC13: =IF(AD13="","VACANT",IF(AD13<TODAY(),"EXPIRED","ACTIVE")) -> ACTIVE | AD13: 47375 | AE13: 0 | AF13: Sungrow (L7 Add.)
A14: 0801 | B14: L08 | C14: 8.01 | D14: Vanderlande Industries Australia Pty Ltd | E14: Vanderlande Industries Australia Pty Ltd | F14: 686.7 | G14: 43282 | H14: 46934 | I14: 10 | J14: 1029.25 | K14: =IF(J14>0,J14*F14,0) -> 706785.98 | L14: -219915.72 | M14: 78859.8 | N14: 11371.8 | O14: 0 | P14: 0 | Q14: =K14+L14+M14+N14+O14+P14 -> 577101.86 | R14: 0 | S14: FIXED 4% | T14: 46569 | U14: Semi-Gross | V14: =IFERROR(MAX((H14-TODAY())/365.25,0),0) -> 1.705681 | W14: =F14*V14 -> 1171.2912 | X14: 990 | Y14: =IF(J14>0,J14-X14,0) -> 39.25 | Z14: =IFERROR(IF(J14>0,(J14-X14)/X14,0),0) -> 0.039646465 | AA14: 288500.00 | AB14: Base year FY2015 7.57%. BG: $288,500. Make good: full open plan. Cleaning $15 psm. | AC14: =IF(AD14="","VACANT",IF(AD14<TODAY(),"EXPIRED","ACTIVE")) -> ACTIVE | AD14: 46934 | AE14: 1029.25 | AF14: Vanderlande Industries
... A19: 1202 | B19: L12 | C19: 12.02 | D19: AEI Insurance Group Pty Ltd | E19: AEI Insurance Group Pty Ltd | F19: 536 | G19: 45642 | H19: 47832 | I19: 6 | J19: 988 | K19: =IF(J19>0,J19*F19,0) -> 529568 | L19: -51200.76 | M19: 24542.16 | N19: 8876.16 | O19: 96647.64 | P19: 30300 | Q19: =K19+L19+M19+N19+O19+P19 -> 638733.2 | R19: 10 | S19: FIXED 4% | T19: 46372 | U19: Semi-Gross | V19: =IFERROR(MAX((H19-TODAY())/365.25,0),0) -> 4.164271 | W19: =F19*V19 -> 2232.0493 | X19: 1010 | Y19: =IF(J19>0,J19-X19,0) -> -22 | Z19: =IFERROR(IF(J19>0,(J19-X19)/X19,0),0) -> -0.021782178 | AA19: 440704.03 | AB19: Option: 6 mths. BG: $440,704 (no expiry). 10 car spaces. Formerly Austbrokers. | AC19: =IF(AD19="","VACANT",IF(AD19<TODAY(),"EXPIRED","ACTIVE")) -> ACTIVE | AD19: 47832 | AE19: 988 | AF19: AEI Insurance Group
A20: 0601 | B20: L06 | C20: 6.01 | D20: Caldas Constructions Pty Ltd | E20: Caldas Constructions Pty Ltd | F20: 186.4 | G20: 46204 | H20: 48395 | I20: 6 | J20: 920 | K20: =IF(J20>0,J20*F20,0) -> 171488 | L20: -512255 | Q20: =K20+L20+M20+N20+O20+P20 -> -340767 | V20: =IFERROR(MAX((H20-TODAY())/365.25,0),0) -> 5.705681 | W20: =F20*V20 -> 1063.5389 | Y20: =IF(J20>0,J20-X20,0) -> 920 | Z20: =IFERROR(IF(J20>0,(J20-X20)/X20,0),0) -> 0 | AB20: Caldas Constructions — new lease 01/07/26 (corrected from 30/06/26), 6 yr term, $920 psm. Prepaid rent held (no BG). Outgoings/cleaning/car park still TBC pending TS confirmation (still NIL on Sept26 TS). Tenant legal name corrected to "Caldas" (previously "Caladas"). | AC20: =IF(AD20="","VACANT",IF(AD20<TODAY(),"EXPIRED","ACTIVE")) -> ACTIVE | AD20: 48395 | AE20: 920 | AF20: Caldas Constructions
A21: 1001 | B21: L10 | C21: 10.01 | D21: VACANT | F21: 438 | K21: =IF(J21>0,J21*F21,0) -> 0 | Q21: =K21+L21+M21+N21+O21+P21 -> 0 | V21: =IFERROR(MAX((H21-TODAY())/365.25,0),0) -> 0 | W21: =F21*V21 -> 0 | Y21: =IF(J21>0,J21-X21,0) -> 0 | Z21: =IFERROR(IF(J21>0,(J21-X21)/X21,0),0) -> 0 | AC21: =IF(AD21="","VACANT",IF(AD21<TODAY(),"EXPIRED","ACTIVE")) -> VACANT | AE21: 0 | AF21: VACANT
A22: 1002 | B22: L10 | C22: 10.02 | D22: VACANT | F22: 349 | K22: =IF(J22>0,J22*F22,0) -> 0 | Q22: =K22+L22+M22+N22+O22+P22 -> 0 | V22: =IFERROR(MAX((H22-TODAY())/365.25,0),0) -> 0 | W22: =F22*V22 -> 0 | Y22: =IF(J22>0,J22-X22,0) -> 0 | Z22: =IFERROR(IF(J22>0,(J22-X22)/X22,0),0) -> 0 | AC22: =IF(AD22="","VACANT",IF(AD22<TODAY(),"EXPIRED","ACTIVE")) -> VACANT | AE22: 0 | AF22: VACANT
A23: 1101 | B23: L11 | C23: 11.01 | D23: Luxasia | E23: LUXASIA | F23: 242.5 | G23: 46296 | H23: 48121 | I23: 5 | J23: 1060 | K23: =IF(J23>0,J23*F23,0) -> 257050 | L23: -25705 | M23: 9728.72 | N23: 4015.8 | O23: 15600 | P23: 6060 | Q23: =K23+L23+M23+N23+O23+P23 -> 266749.52 | R23: 2 | S23: FIXED 3.75% | T23: 46661 | U23: Semi-Gross | V23: =IFERROR(MAX((H23-TODAY())/365.25,0),0) -> 4.9555099 | W23: =F23*V23 -> 1201.7112 | X23: 1060 | Y23: =IF(J23>0,J23-X23,0) -> 0 | Z23: =IFERROR(IF(J23>0,(J23-X23)/X23,0),0) -> 0 | AA23: 181149 | AB23: Break at 3 years. Lease commenced 1/10/26, 5 yr term, $1,060 psm. Incentive: landlord fitout contribution $369,812.50 (see Fitout Costs register) + rent abatement totalling $192,787.50 over the term — Yr 1-3 $25,705 pa (reflected in Abatement PA), Yr 4-5 $57,836.25 pa. Abatement PA will need manual updating to -$57,836.25 from the Yr 4 anniversary (1/10/29). | AC23: =IF(AD23="","VACANT",IF(AD23<TODAY(),"EXPIRED","ACTIVE")) -> ACTIVE | AD23: 48121 | AE23: 1060 | AF23: Luxasia
A24: 1102 | B24: L11 | C24: 11.02 | D24: Haskoning Australia Pty Ltd | E24: Haskoning Australia Pty Ltd | F24: 548 | G24: 46296 | H24: 48487 | I24: 6 | J24: 1040 | K24: =IF(J24>0,J24*F24,0) -> 569920 | L24: -111845.33 | Q24: =K24+L24+M24+N24+O24+P24 -> 458074.67 | S24: FIXED 3.5% | T24: 46661 | V24: =IFERROR(MAX((H24-TODAY())/365.25,0),0) -> 5.9575633 | W24: =F24*V24 -> 3264.7447 | X24: 1040 | Y24: =IF(J24>0,J24-X24,0) -> 0 | Z24: =IFERROR(IF(J24>0,(J24-X24)/X24,0),0) -> 0 | AB24: Haskoning Australia Pty Ltd — new lease commencing 01/10/26, 6 yr term, $1,040 psm, fixed 3.5% review. Fitout contribution $750,400 (landlord funded). Outgoings/cleaning/car park TBC pending TS confirmation. Next review date estimated. | AC24: =IF(AD24="","VACANT",IF(AD24<TODAY(),"EXPIRED","ACTIVE")) -> ACTIVE | AD24: 49582 | AE24: 1040 | AF24: Haskoning Australia
A25: TOTALS / BUILDING SUMMARY | F25: =SUM(F3:F24) -> 8940.9 | K25: =SUM(K3:K24) -> 7981402 | L25: =SUM(L3:L24) -> -2123734.2 | Q25: =SUM(Q3:Q24) -> 6606792.7 | V25: =IFERROR(SUMPRODUCT((H3:H24<>"")*F3:F24*MAX((H3:H24-TODAY())/365.25,0))/SUMPRODUCT((H3:H24<>"")*F3:F24),0) -> 5.9575633 | W25: =SUM(W3:W24) -> 29867.852
A26: OCCUPANCY % | D26: Occupied NLA | E26: =SUMPRODUCT((H3:H24<>"")*F3:F24) -> 8153.9 | F26: Vacant NLA | G26: =SUMPRODUCT((H3:H24="")*F3:F24) -> 787 | H26: Total NLA | I26: =SUM(F3:F24) -> 8940.9 | J26: Occupancy % | K26: =IFERROR(E26/I26,0) -> 0.91197754 | L26: Vacancy % | M26: =IFERROR(G26/I26,0) -> 0.088022459

Sheet Dashboard
A1: 1 ELIZABETH PLAZA, NORTH SYDNEY — ASSET MANAGEMENT DASHBOARD
A2: As at 30 September 2026 | Data sourced from Input Data tab | All amounts in AUD
B4: TOTAL NLA | D4: OCCUPIED NLA | F4: VACANT NLA | H4: OCCUPANCY | J4: VACANCY | L4: SUITES
B5: =SUM('Input Data'!F3:F24) -> 8940.9 | D5: =SUMPRODUCT(('Input Data'!H3:H24<>"")*'Input Data'!F3:F24) -> 8153.9 | F5: =SUMPRODUCT(('Input Data'!H3:H24="")*'Input Data'!F3:F24) -> 787 | H5: =IFERROR(SUMPRODUCT(('Input Data'!H3:H24<>"")*'Input Data'!F3:F24)/SUM('Input Data'!F3:F24),0) -> 0.91197754 | J5: =IFERROR(SUMPRODUCT(('Input Data'!H3:H24="")*'Input Data'!F3:F24)/SUM('Input Data'!F3:F24),0) -> 0.088022459 | L5: 20 occ | 2 vacant
B8: GROSS INCOME PA | D8: NET EFFECTIVE PA | F8: ABATEMENT PA | H8: WALE by NLA | J8: WALE by Income | L8: OUTGOINGS %
B9: =SUM('Input Data'!K3:K24) -> 7981402 | D9: =SUM('Input Data'!Q3:Q24) -> 6606792.7 | F9: =SUM('Input Data'!L3:L24) -> -2123734.2 | H9: =E14 -> 3.9091468 | J9: =E15 -> 3.8025989 | L9: 92.3%
B12: WEIGHTED AVERAGE LEASE EXPIRY (WALE)
B13: Measure | E13: WALE | F13: Basis
B14: WALE by NLA | E14: =IFERROR(SUMPRODUCT(('Input Data'!AD3:AD24>TODAY())*('Input Data'!AE3:AE24>0)*'Input Data'!F3:F24*('Input Data'!AD3:AD24-TODAY())/365.25)/SUMPRODUCT(('Input Data'!AD3:AD24>TODAY())*('Input Data'!AE3:AE24>0)*'Input Data'!F3:F24),0) -> 3.9091468 | F14: Area-weighted average of remaining lease terms (occupied suites only)
B15: WALE by Income | E15: =IFERROR(SUMPRODUCT(('Input Data'!AD3:AD24>TODAY())*('Input Data'!AE3:AE24>0)*'Input Data'!AE3:AE24*'Input Data'!F3:F24*('Input Data'!AD3:AD24-TODAY())/365.25)/SUMPRODUCT(('Input Data'!AD3:AD24>TODAY())*('Input Data'!AE3:AE24>0)*'Input Data'!AE3:AE24*'Input Data'!F3:F24),0) -> 3.8025989 | F15: Income-weighted average of remaining lease terms
B17: LEASE EXPIRY PROFILE — BY INCOME & AREA (5 YEAR FORWARD VIEW)
B18: Expiry Year | D18: Net Effective ($) | F18: Income % | G18: NLA (sqm) | H18: Area % | I18: # Leases | J18: Tenants Expiring
B19: 2026 | D19: =SUMPRODUCT(('Input Data'!AD3:AD24<>"")*('Input Data'!AD3:AD24<=DATE(2026,12,31))*'Input Data'!AE3:AE24*'Input Data'!F3:F24) -> 0 | F19: =IFERROR(D19/(SUMPRODUCT(('Input Data'!AD3:AD24>TODAY())*('Input Data'!AE3:AE24>0)*'Input Data'!AE3:AE24*'Input Data'!F3:F24)),0) -> 0 | G19: =SUMPRODUCT(('Input Data'!AD3:AD24<>"")*('Input Data'!AD3:AD24<=DATE(2026,12,31))*'Input Data'!F3:F24) -> 0 | H19: =IFERROR(G19/(SUMPRODUCT(('Input Data'!AD3:AD24>TODAY())*('Input Data'!AE3:AE24>0)*'Input Data'!F3:F24)),0) -> 0 | I19: =SUMPRODUCT(('Input Data'!AD3:AD24<>"")*('Input Data'!AD3:AD24<=DATE(2026,12,31))*1) -> 0 | J19: =IFERROR(MID(IF(('Input Data'!AD3<>"")*('Input Data'!AD3<=DATE(2026,12,31)),", "&'Input Data'!AF3&" ("&'Input Data'!C3&")","")&IF(('Input Data'!AD4<>"")*('Input Data'!AD4<=DATE(2026,12,31)),", "&'Input Data'!AF4&" ("&'Input Data'!C4&")","")&IF(('Input Data'!AD5<>"")*('Input Data'!AD5<=DATE(2026,12,31)),", "&'Input Data'!AF5&" ("&'Input Data'!C5&")","")&IF(('Input Data'!AD6<>"")*('Input Data'!AD6<=DATE(2026,12,31)),", "&'Input Data'!AF6&" ("&'Input Data'!C6&")","")&IF(('Input Data'!AD7<>"")*('Input Data'!AD7<=DATE(2026,12,31)),", "&'Input Data'!AF7&" ("&'Input Data'!C7&")","")&IF(('Input Data'!AD8<>"")*('Input Data'!AD8<=DATE(2026,12,31)),", "&'Input Data'!AF8&" ("&'Input Data'!C8&")","")&IF(('Input Data'!AD9<>"")*('Input Data'!AD9<=DATE(2026,12,31)),", "&'Input Data'!AF9&" ("&'Input Data'!C9&")","")&IF(('Input Data'!AD10<>"")*('Input Data'!AD10<=DATE(2026,12,31)),", "&'Input Data'!AF10&" ("&'Input Data'!C10&")","")&IF(('Input Data'!AD11<>"")*('Input Data'!AD11<=DATE(2026,12,31)),", "&'Input Data'!AF11&" ("&'Input Data'!C11&")","")&IF(('Input Data'!AD12<>"")*('Input Data'!AD12<=DATE(2026,12,31)),", "&'Input Data'!AF12&" ("&'Input Data'!C12&")","")&IF(('Input Data'!AD13<>"")*('Input Data'!AD13<=DATE(2026,12,31)),", "&'Input Data'!AF13&" ("&'Input Data'!C13&")","")&IF(('Input Data'!AD14<>"")*('Input Data'!AD14<=DATE(2026,12,31)),", "&'Input Data'!AF14&" ("&'Input Data'!C14&")","")&IF(('Input Data'!AD15<>"")*('Input Data'!AD15<=DATE(2026,12,31)),", "&'Input Data'!AF15&" ("&'Input Data'!C15&")","")&IF(('Input Data'!AD16<>"")*('Input Data'!AD16<=DATE(2026,12,31)),", "&'Input Data'!AF16&" ("&'Input Data'!C16&")","")&IF(('Input Data'!AD17<>"")*('Input Data'!AD17<=DATE(2026,12,31)),", "&'Input Data'!AF17&" ("&'Input Data'!C17&")","")&IF(('Input Data'!AD18<>"")*('Input Data'!AD18<=DATE(2026,12,31)),", "&'Input Data'!AF18&" ("&'Input Data'!C18&")","")&IF(('Input Data'!AD19<>"")*('Input Data'!AD19<=DATE(2026,12,31)),", "&'Input Data'!AF19&" ("&'Input Data'!C19&")","")&IF(('Input Data'!AD20<>"")*('Input Data'!AD20<=DATE(2026,12,31)),", "&'Input Data'!AF20&" ("&'Input Data'!C20&")","")&IF(('Input Data'!AD21<>"")*('Input Data'!AD21<=DATE(2026,12,31)),", "&'Input Data'!AF21&" ("&'Input Data'!C21&")","")&IF(('Input Data'!AD22<>"")*('Input Data'!AD22<=DATE(2026,12,31)),", "&'Input Data'!AF22&" ("&'Input Data'!C22&")","")&IF(('Input Data'!AD23<>"")*('Input Data'!AD23<=DATE(2026,12,31)),", "&'Input Data'!AF23&" ("&'Input Data'!C23&")","")&IF(('Input Data'!AD24<>"")*('Input Data'!AD24<=DATE(2026,12,31)),", "&'Input Data'!AF24&" ("&'Input Data'!C24&")",""),3,999),"—")
B20: 2027 | D20: {=SUMPRODUCT(('Input Data'!AD3:AD24>TODAY())*(YEAR('Input Data'!AD3:AD24)=2027)*('Input Data'!AE3:AE24>0)*'Input Data'!AE3:AE24*'Input Data'!F3:F24)} -> 683153.04 | F20: =IFERROR(D20/(SUMPRODUCT(('Input Data'!AD3:AD24>TODAY())*('Input Data'!AE3:AE24>0)*'Input Data'!AE3:AE24*'Input Data'!F3:F24)),0) -> 0.085593112 | G20: =SUMPRODUCT(('Input Data'!AD3:AD24>TODAY())*(YEAR('Input Data'!AD3:AD24)=2027)*('Input Data'!AE3:AE24>0)*'Input Data'!F3:F24) -> 642.7 | H20: =IFERROR(G20/(SUMPRODUCT(('Input Data'!AD3:AD24>TODAY())*('Input Data'!AE3:AE24>0)*'Input Data'!F3:F24)),0) -> 0.082520158 | I20: =SUMPRODUCT(('Input Data'!AD3:AD24>TODAY())*(YEAR('Input Data'!AD3:AD24)=2027)*('Input Data'!AE3:AE24>0)*1) -> 2 | J20: =IFERROR(MID(IF(('Input Data'!AD3>TODAY())*(YEAR('Input Data'!AD3)=2027)*('Input Data'!AE3>0),", "&'Input Data'!AF3&" ("&'Input Data'!C3&")","")&IF(('Input Data'!AD4>TODAY())*(YEAR('Input Data'!AD4)=2027)*('Input Data'!AE4>0),", "&'Input Data'!AF4&" ("&'Input Data'!C4&")","")&IF(('Input Data'!AD5>TODAY())*(YEAR('Input Data'!AD5)=2027)*('Input Data'!AE5>0),", "&'Input Data'!AF5&" ("&'Input Data'!C5&")","")&IF(('Input Data'!AD6>TODAY())*(YEAR('Input Data'!AD6)=2027)*('Input Data'!AE6>0),", "&'Input Data'!AF6&" ("&'Input Data'!C6&")","")&IF(('Input Data'!AD7>TODAY())*(YEAR('Input Data'!AD7)=2027)*('Input Data'!AE7>0),", "&'Input Data'!AF7&" ("&'Input Data'!C7&")","")&IF(('Input Data'!AD8>TODAY())*(YEAR('Input Data'!AD8)=2027)*('Input Data'!AE8>0),", "&'Input Data'!AF8&" ("&'Input Data'!C8&")","")&IF(('Input Data'!AD9>TODAY())*(YEAR('Input Data'!AD9)=2027)*('Input Data'!AE9>0),", "&'Input Data'!AF9&" ("&'Input Data'!C9&")","")&IF(('Input Data'!AD10>TODAY())*(YEAR('Input Data'!AD10)=2027)*('Input Data'!AE10>0),", "&'Input Data'!AF10&" ("&'Input Data'!C10&")","")&IF(('Input Data'!AD11>TODAY())*(YEAR('Input Data'!AD11)=2027)*('Input Data'!AE11>0),", "&'Input Data'!AF11&" ("&'Input Data'!C11&")","")&IF(('Input Data'!AD12>TODAY())*(YEAR('Input Data'!AD12)=2027)*('Input Data'!AE12>0),", "&'Input Data'!AF12&" ("&'Input Data'!C12&")","")&IF(('Input Data'!AD13>TODAY())*(YEAR('Input Data'!AD13)=2027)*('Input Data'!AE13>0),", "&'Input Data'!AF13&" ("&'Input Data'!C13&")","")&IF(('Input Data'!AD14>TODAY())*(YEAR('Input Data'!AD14)=2027)*('Input Data'!AE14>0),", "&'Input Data'!AF14&" ("&'Input Data'!C14&")","")&IF(('Input Data'!AD15>TODAY())*(YEAR('Input Data'!AD15)=2027)*('Input Data'!AE15>0),", "&'Input Data'!AF15&" ("&'Input Data'!C15&")","")&IF(('Input Data'!AD16>TODAY())*(YEAR('Input Data'!AD16)=2027)*('Input Data'!AE16>0),", "&'Input Data'!AF16&" ("&'Input Data'!C16&")","")&IF(('Input Data'!AD17>TODAY())*(YEAR('Input Data'!AD17)=2027)*('Input Data'!AE17>0),", "&'Input Data'!AF17&" ("&'Input Data'!C17&")","")&IF(('Input Data'!AD18>TODAY())*(YEAR('Input Data'!AD18)=2027)*('Input Data'!AE18>0),", "&'Input Data'!AF18&" ("&'Input Data'!C18&")","")&IF(('Input Data'!AD19>TODAY())*(YEAR('Input Data'!AD19)=2027)*('Input Data'!AE19>0),", "&'Input Data'!AF19&" ("&'Input Data'!C19&")","")&IF(('Input Data'!AD20>TODAY())*(YEAR('Input Data'!AD20)=2027)*('Input Data'!AE20>0),", "&'Input Data'!AF20&" ("&'Input Data'!C20&")","")&IF(('Input Data'!AD21>TODAY())*(YEAR('Input Data'!AD21)=2027)*('Input Data'!AE21>0),", "&'Input Data'!AF21&" ("&'Input Data'!C21&")","")&IF(('Input Data'!AD22>TODAY())*(YEAR('Input Data'!AD22)=2027)*('Input Data'!AE22>0),", "&'Input Data'!AF22&" ("&'Input Data'!C22&")","")&IF(('Input Data'!AD23>TODAY())*(YEAR('Input Data'!AD23)=2027)*('Input Data'!AE23>0),", "&'Input Data'!AF23&" ("&'Input Data'!C23&")","")&IF(('Input Data'!AD24>TODAY())*(YEAR('Input Data'!AD24)=2027)*('Input Data'!AE24>0),", "&'Input Data'!AF24&" ("&'Input Data'!C24&")",""),3,999),"—") -> Keeping Company (6.03), Pitt & Sherry (9.01)
B21: 2028 | D21: =SUMPRODUCT(('Input Data'!AD3:AD24>TODAY())*(YEAR('Input Data'!AD3:AD24)=2028)*('Input Data'!AE3:AE24>0)*'Input Data'!AE3:AE24*'Input Data'!F3:F24) -> 857128.71 | F21: =IFERROR(D21/(SUMPRODUCT(('Input Data'!AD3:AD24>TODAY())*('Input Data'!AE3:AE24>0)*'Input Data'!AE3:AE24*'Input Data'!F3:F24)),0) -> 0.10739075 | G21: =SUMPRODUCT(('Input Data'!AD3:AD24>TODAY())*(YEAR('Input Data'!AD3:AD24)=2028)*('Input Data'!AE3:AE24>0)*'Input Data'!F3:F24) -> 794.4 | H21: =IFERROR(G21/(SUMPRODUCT(('Input Data'!AD3:AD24>TODAY())*('Input Data'!AE3:AE24>0)*'Input Data'!F3:F24)),0) -> 0.10199784 | I21: =SUMPRODUCT(('Input Data'!AD3:AD24>TODAY())*(YEAR('Input Data'!AD3:AD24)=2028)*('Input Data'!AE3:AE24>0)*1) -> 2 | J21: =IFERROR(MID(IF(('Input Data'!AD3>TODAY())*(YEAR('Input Data'!AD3)=2028)*('Input Data'!AE3>0),", "&'Input Data'!AF3&" ("&'Input Data'!C3&")","")&IF(('Input Data'!AD4>TODAY())*(YEAR('Input Data'!AD4)=2028)*('Input Data'!AE4>0),", "&'Input Data'!AF4&" ("&'Input Data'!C4&")","")&IF(('Input Data'!AD5>TODAY())*(YEAR('Input Data'!AD5)=2028)*('Input Data'!AE5>0),", "&'Input Data'!AF5&" ("&'Input Data'!C5&")","")&IF(('Input Data'!AD6>TODAY())*(YEAR('Input Data'!AD6)=2028)*('Input Data'!AE6>0),", "&'Input Data'!AF6&" ("&'Input Data'!C6&")","")&IF(('Input Data'!AD7>TODAY())*(YEAR('Input Data'!AD7)=2028)*('Input Data'!AE7>0),", "&'Input Data'!AF7&" ("&'Input Data'!C7&")","")&IF(('Input Data'!AD8>TODAY())*(YEAR('Input Data'!AD8)=2028)*('Input Data'!AE8>0),", "&'Input Data'!AF8&" ("&'Input Data'!C8&")","")&IF(('Input Data'!AD9>TODAY())*(YEAR('Input Data'!AD9)=2028)*('Input Data'!AE9>0),", "&'Input Data'!AF9&" ("&'Input Data'!C9&")","")&IF(('Input Data'!AD10>TODAY())*(YEAR('Input Data'!AD10)=2028)*('Input Data'!AE10>0),", "&'Input Data'!AF10&" ("&'Input Data'!C10&")","")&IF(('Input Data'!AD11>TODAY())*(YEAR('Input Data'!AD11)=2028)*('Input Data'!AE11>0),", "&'Input Data'!AF11&" ("&'Input Data'!C11&")","")&IF(('Input Data'!AD12>TODAY())*(YEAR('Input Data'!AD12)=2028)*('Input Data'!AE12>0),", "&'Input Data'!AF12&" ("&'Input Data'!C12&")","")&IF(('Input Data'!AD13>TODAY())*(YEAR('Input Data'!AD13)=2028)*('Input Data'!AE13>0),", "&'Input Data'!AF13&" ("&'Input Data'!C13&")","")&IF(('Input Data'!AD14>TODAY())*(YEAR('Input Data'!AD14)=2028)*('Input Data'!AE14>0),", "&'Input Data'!AF14&" ("&'Input Data'!C14&")","")&IF(('Input Data'!AD15>TODAY())*(YEAR('Input Data'!AD15)=2028)*('Input Data'!AE15>0),", "&'Input Data'!AF15&" ("&'Input Data'!C15&")","")&IF(('Input Data'!AD16>TODAY())*(YEAR('Input Data'!AD16)=2028)*('Input Data'!AE16>0),", "&'Input Data'!AF16&" ("&'Input Data'!C16&")","")&IF(('Input Data'!AD17>TODAY())*(YEAR('Input Data'!AD17)=2028)*('Input Data'!AE17>0),", "&'Input Data'!AF17&" ("&'Input Data'!C17&")","")&IF(('Input Data'!AD18>TODAY())*(YEAR('Input Data'!AD18)=2028)*('Input Data'!AE18>0),", "&'Input Data'!AF18&" ("&'Input Data'!C18&")","")&IF(('Input Data'!AD19>TODAY())*(YEAR('Input Data'!AD19)=2028)*('Input Data'!AE19>0),", "&'Input Data'!AF19&" ("&'Input Data'!C19&")","")&IF(('Input Data'!AD20>TODAY())*(YEAR('Input Data'!AD20)=2028)*('Input Data'!AE20>0),", "&'Input Data'!AF20&" ("&'Input Data'!C20&")","")&IF(('Input Data'!AD21>TODAY())*(YEAR('Input Data'!AD21)=2028)*('Input Data'!AE21>0),", "&'Input Data'!AF21&" ("&'Input Data'!C21&")","")&IF(('Input Data'!AD22>TODAY())*(YEAR('Input Data'!AD22)=2028)*('Input Data'!AE22>0),", "&'Input Data'!AF22&" ("&'Input Data'!C22&")","")&IF(('Input Data'!AD23>TODAY())*(YEAR('Input Data'!AD23)=2028)*('Input Data'!AE23>0),", "&'Input Data'!AF23&" ("&'Input Data'!C23&")","")&IF(('Input Data'!AD24>TODAY())*(YEAR('Input Data'!AD24)=2028)*('Input Data'!AE24>0),", "&'Input Data'!AF24&" ("&'Input Data'!C24&")",""),3,999),"—") -> Sydney Smiletree (3.01), Vanderlande Industries (8.01)
B22: 2029 | D22: =SUMPRODUCT(('Input Data'!AD3:AD24>TODAY())*(YEAR('Input Data'!AD3:AD24)=2029)*('Input Data'!AE3:AE24>0)*'Input Data'!AE3:AE24*'Input Data'!F3:F24) -> 2340041 | F22: =IFERROR(D22/(SUMPRODUCT(('Input Data'!AD3:AD24>TODAY())*('Input Data'!AE3:AE24>0)*'Input Data'!AE3:AE24*'Input Data'!F3:F24)),0) -> 0.29318671 | G22: =SUMPRODUCT(('Input Data'!AD3:AD24>TODAY())*(YEAR('Input Data'!AD3:AD24)=2029)*('Input Data'!AE3:AE24>0)*'Input Data'!F3:F24) -> 1923.6 | H22: =IFERROR(G22/(SUMPRODUCT(('Input Data'!AD3:AD24>TODAY())*('Input Data'!AE3:AE24>0)*'Input Data'!F3:F24)),0) -> 0.24698269 | I22: =SUMPRODUCT(('Input Data'!AD3:AD24>TODAY())*(YEAR('Input Data'!AD3:AD24)=2029)*('Input Data'!AE3:AE24>0)*1) -> 5 | J22: =IFERROR(MID(IF(('Input Data'!AD3>TODAY())*(YEAR('Input Data'!AD3)=2029)*('Input Data'!AE3>0),", "&'Input Data'!AF3&" ("&'Input Data'!C3&")","")&IF(('Input Data'!AD4>TODAY())*(YEAR('Input Data'!AD4)=2029)*('Input Data'!AE4>0),", "&'Input Data'!AF4&" ("&'Input Data'!C4&")","")&IF(('Input Data'!AD5>TODAY())*(YEAR('Input Data'!AD5)=2029)*('Input Data'!AE5>0),", "&'Input Data'!AF5&" ("&'Input Data'!C5&")","")&IF(('Input Data'!AD6>TODAY())*(YEAR('Input Data'!AD6)=2029)*('Input Data'!AE6>0),", "&'Input Data'!AF6&" ("&'Input Data'!C6&")","")&IF(('Input Data'!AD7>TODAY())*(YEAR('Input Data'!AD7)=2029)*('Input Data'!AE7>0),", "&'Input Data'!AF7&" ("&'Input Data'!C7&")","")&IF(('Input Data'!AD8>TODAY())*(YEAR('Input Data'!AD8)=2029)*('Input Data'!AE8>0),", "&'Input Data'!AF8&" ("&'Input Data'!C8&")","")&IF(('Input Data'!AD9>TODAY())*(YEAR('Input Data'!AD9)=2029)*('Input Data'!AE9>0),", "&'Input Data'!AF9&" ("&'Input Data'!C9&")","")&IF(('Input Data'!AD10>TODAY())*(YEAR('Input Data'!AD10)=2029)*('Input Data'!AE10>0),", "&'Input Data'!AF10&" ("&'Input Data'!C10&")","")&IF(('Input Data'!AD11>TODAY())*(YEAR('Input Data'!AD11)=2029)*('Input Data'!AE11>0),", "&'Input Data'!AF11&" ("&'Input Data'!C11&")","")&IF(('Input Data'!AD12>TODAY())*(YEAR('Input Data'!AD12)=2029)*('Input Data'!AE12>0),", "&'Input Data'!AF12&" ("&'Input Data'!C12&")","")&IF(('Input Data'!AD13>TODAY())*(YEAR('Input Data'!AD13)=2029)*('Input Data'!AE13>0),", "&'Input Data'!AF13&" ("&'Input Data'!C13&")","")&IF(('Input Data'!AD14>TODAY())*(YEAR('Input Data'!AD14)=2029)*('Input Data'!AE14>0),", "&'Input Data'!AF14&" ("&'Input Data'!C14&")","")&IF(('Input Data'!AD15>TODAY())*(YEAR('Input Data'!AD15)=2029)*('Input Data'!AE15>0),", "&'Input Data'!AF15&" ("&'Input Data'!C15&")","")&IF(('Input Data'!AD16>TODAY())*(YEAR('Input Data'!AD16)=2029)*('Input Data'!AE16>0),", "&'Input Data'!AF16&" ("&'Input Data'!C16&")","")&IF(('Input Data'!AD17>TODAY())*(YEAR('Input Data'!AD17)=2029)*('Input Data'!AE17>0),", "&'Input Data'!AF17&" ("&'Input Data'!C17&")","")&IF(('Input Data'!AD18>TODAY())*(YEAR('Input Data'!AD18)=2029)*('Input Data'!AE18>0),", "&'Input Data'!AF18&" ("&'Input Data'!C18&")","")&IF(('Input Data'!AD19>TODAY())*(YEAR('Input Data'!AD19)=2029)*('Input Data'!AE19>0),", "&'Input Data'!AF19&" ("&'Input Data'!C19&")","")&IF(('Input Data'!AD20>TODAY())*(YEAR('Input Data'!AD20)=2029)*('Input Data'!AE20>0),", "&'Input Data'!AF20&" ("&'Input Data'!C20&")","")&IF(('Input Data'!AD21>TODAY())*(YEAR('Input Data'!AD21)=2029)*('Input Data'!AE21>0),", "&'Input Data'!AF21&" ("&'Input Data'!C21&")","")&IF(('Input Data'!AD22>TODAY())*(YEAR('Input Data'!AD22)=2029)*('Input Data'!AE22>0),", "&'Input Data'!AF22&" ("&'Input Data'!C22&")","")&IF(('Input Data'!AD23>TODAY())*(YEAR('Input Data'!AD23)=2029)*('Input Data'!AE23>0),", "&'Input Data'!AF23&" ("&'Input Data'!C23&")","")&IF(('Input Data'!AD24>TODAY())*(YEAR('Input Data'!AD24)=2029)*('Input Data'!AE24>0),", "&'Input Data'!AF24&" ("&'Input Data'!C24&")",""),3,999),"—") -> Asterx (MediRecords) (5.03), Auctionsplus (5.04), Sungrow (L6) (6.02), Sungrow (L7 Main) (7.01), Smile Partners Australia (9.02)
B23: 2030 | D23: =SUMPRODUCT(('Input Data'!AD3:AD24>TODAY())*(YEAR('Input Data'!AD3:AD24)=2030)*('Input Data'!AE3:AE24>0)*'Input Data'!AE3:AE24*'Input Data'!F3:F24) -> 896257.06 | F23: =IFERROR(D23/(SUMPRODUCT(('Input Data'!AD3:AD24>TODAY())*('Input Data'!AE3:AE24>0)*'Input Data'!AE3:AE24*'Input Data'!F3:F24)),0) -> 0.11229318 | G23: =SUMPRODUCT(('Input Data'!AD3:AD24>TODAY())*(YEAR('Input Data'!AD3:AD24)=2030)*('Input Data'!AE3:AE24>0)*'Input Data'!F3:F24) -> 903.3 | H23: =IFERROR(G23/(SUMPRODUCT(('Input Data'!AD3:AD24>TODAY())*('Input Data'!AE3:AE24>0)*'Input Data'!F3:F24)),0) -> 0.11598018 | I23: =SUMPRODUCT(('Input Data'!AD3:AD24>TODAY())*(YEAR('Input Data'!AD3:AD24)=2030)*('Input Data'!AE3:AE24>0)*1) -> 3 | J23: =IFERROR(MID(IF(('Input Data'!AD3>TODAY())*(YEAR('Input Data'!AD3)=2030)*('Input Data'!AE3>0),", "&'Input Data'!AF3&" ("&'Input Data'!C3&")","")&IF(('Input Data'!AD4>TODAY())*(YEAR('Input Data'!AD4)=2030)*('Input Data'!AE4>0),", "&'Input Data'!AF4&" ("&'Input Data'!C4&")","")&IF(('Input Data'!AD5>TODAY())*(YEAR('Input Data'!AD5)=2030)*('Input Data'!AE5>0),", "&'Input Data'!AF5&" ("&'Input Data'!C5&")","")&IF(('Input Data'!AD6>TODAY())*(YEAR('Input Data'!AD6)=2030)*('Input Data'!AE6>0),", "&'Input Data'!AF6&" ("&'Input Data'!C6&")","")&IF(('Input Data'!AD7>TODAY())*(YEAR('Input Data'!AD7)=2030)*('Input Data'!AE7>0),", "&'Input Data'!AF7&" ("&'Input Data'!C7&")","")&IF(('Input Data'!AD8>TODAY())*(YEAR('Input Data'!AD8)=2030)*('Input Data'!AE8>0),", "&'Input Data'!AF8&" ("&'Input Data'!C8&")","")&IF(('Input Data'!AD9>TODAY())*(YEAR('Input Data'!AD9)=2030)*('Input Data'!AE9>0),", "&'Input Data'!AF9&" ("&'Input Data'!C9&")","")&IF(('Input Data'!AD10>TODAY())*(YEAR('Input Data'!AD10)=2030)*('Input Data'!AE10>0),", "&'Input Data'!AF10&" ("&'Input Data'!C10&")","")&IF(('Input Data'!AD11>TODAY())*(YEAR('Input Data'!AD11)=2030)*('Input Data'!AE11>0),", "&'Input Data'!AF11&" ("&'Input Data'!C11&")","")&IF(('Input Data'!AD12>TODAY())*(YEAR('Input Data'!AD12)=2030)*('Input Data'!AE12>0),", "&'Input Data'!AF12&" ("&'Input Data'!C12&")","")&IF(('Input Data'!AD13>TODAY())*(YEAR('Input Data'!AD13)=2030)*('Input Data'!AE13>0),", "&'Input Data'!AF13&" ("&'Input Data'!C13&")","")&IF(('Input Data'!AD14>TODAY())*(YEAR('Input Data'!AD14)=2030)*('Input Data'!AE14>0),", "&'Input Data'!AF14&" ("&'Input Data'!C14&")","")&IF(('Input Data'!AD15>TODAY())*(YEAR('Input Data'!AD15)=2030)*('Input Data'!AE15>0),", "&'Input Data'!AF15&" ("&'Input Data'!C15&")","")&IF(('Input Data'!AD16>TODAY())*(YEAR('Input Data'!AD16)=2030)*('Input Data'!AE16>0),", "&'Input Data'!AF16&" ("&'Input Data'!C16&")","")&IF(('Input Data'!AD17>TODAY())*(YEAR('Input Data'!AD17)=2030)*('Input Data'!AE17>0),", "&'Input Data'!AF17&" ("&'Input Data'!C17&")","")&IF(('Input Data'!AD18>TODAY())*(YEAR('Input Data'!AD18)=2030)*('Input Data'!AE18>0),", "&'Input Data'!AF18&" ("&'Input Data'!C18&")","")&IF(('Input Data'!AD19>TODAY())*(YEAR('Input Data'!AD19)=2030)*('Input Data'!AE19>0),", "&'Input Data'!AF19&" ("&'Input Data'!C19&")","")&IF(('Input Data'!AD20>TODAY())*(YEAR('Input Data'!AD20)=2030)*('Input Data'!AE20>0),", "&'Input Data'!AF20&" ("&'Input Data'!C20&")","")&IF(('Input Data'!AD21>TODAY())*(YEAR('Input Data'!AD21)=2030)*('Input Data'!AE21>0),", "&'Input Data'!AF21&" ("&'Input Data'!C21&")","")&IF(('Input Data'!AD22>TODAY())*(YEAR('Input Data'!AD22)=2030)*('Input Data'!AE22>0),", "&'Input Data'!AF22&" ("&'Input Data'!C22&")","")&IF(('Input Data'!AD23>TODAY())*(YEAR('Input Data'!AD23)=2030)*('Input Data'!AE23>0),", "&'Input Data'!AF23&" ("&'Input Data'!C23&")","")&IF(('Input Data'!AD24>TODAY())*(YEAR('Input Data'!AD24)=2030)*('Input Data'!AE24>0),", "&'Input Data'!AF24&" ("&'Input Data'!C24&")",""),3,999),"—") -> Can Too Foundation (8.03), Hulsbosch Design (12.01), AEI Insurance Group (12.02)
B24: 2031+ | D24: =SUMPRODUCT(('Input Data'!AD3:AD24>TODAY())*(YEAR('Input Data'!AD3:AD24)>=2031)*('Input Data'!AE3:AE24>0)*'Input Data'!AE3:AE24*'Input Data'!F3:F24) -> 3204822.3 | F24: =IFERROR(D24/(SUMPRODUCT(('Input Data'!AD3:AD24>TODAY())*('Input Data'!AE3:AE24>0)*'Input Data'!AE3:AE24*'Input Data'!F3:F24)),0) -> 0.40153625 | G24: =SUMPRODUCT(('Input Data'!AD3:AD24>TODAY())*(YEAR('Input Data'!AD3:AD24)>=2031)*('Input Data'!AE3:AE24>0)*'Input Data'!F3:F24) -> 3524.4 | H24: =IFERROR(G24/(SUMPRODUCT(('Input Data'!AD3:AD24>TODAY())*('Input Data'!AE3:AE24>0)*'Input Data'!F3:F24)),0) -> 0.45251913 | I24: =SUMPRODUCT(('Input Data'!AD3:AD24>TODAY())*(YEAR('Input Data'!AD3:AD24)>=2031)*('Input Data'!AE3:AE24>0)*1) -> 7 | J24: =IFERROR(MID(IF(('Input Data'!AD3>TODAY())*(YEAR('Input Data'!AD3)>=2031)*('Input Data'!AE3>0),", "&'Input Data'!AF3&" ("&'Input Data'!C3&")","")&IF(('Input Data'!AD4>TODAY())*(YEAR('Input Data'!AD4)>=2031)*('Input Data'!AE4>0),", "&'Input Data'!AF4&" ("&'Input Data'!C4&")","")&IF(('Input Data'!AD5>TODAY())*(YEAR('Input Data'!AD5)>=2031)*('Input Data'!AE5>0),", "&'Input Data'!AF5&" ("&'Input Data'!C5&")","")&IF(('Input Data'!AD6>TODAY())*(YEAR('Input Data'!AD6)>=2031)*('Input Data'!AE6>0),", "&'Input Data'!AF6&" ("&'Input Data'!C6&")","")&IF(('Input Data'!AD7>TODAY())*(YEAR('Input Data'!AD7)>=2031)*('Input Data'!AE7>0),", "&'Input Data'!AF7&" ("&'Input Data'!C7&")","")&IF(('Input Data'!AD8>TODAY())*(YEAR('Input Data'!AD8)>=2031)*('Input Data'!AE8>0),", "&'Input Data'!AF8&" ("&'Input Data'!C8&")","")&IF(('Input Data'!AD9>TODAY())*(YEAR('Input Data'!AD9)>=2031)*('Input Data'!AE9>0),", "&'Input Data'!AF9&" ("&'Input Data'!C9&")","")&IF(('Input Data'!AD10>TODAY())*(YEAR('Input Data'!AD10)>=2031)*('Input Data'!AE10>0),", "&'Input Data'!AF10&" ("&'Input Data'!C10&")","")&IF(('Input Data'!AD11>TODAY())*(YEAR('Input Data'!AD11)>=2031)*('Input Data'!AE11>0),", "&'Input Data'!AF11&" ("&'Input Data'!C11&")","")&IF(('Input Data'!AD12>TODAY())*(YEAR('Input Data'!AD12)>=2031)*('Input Data'!AE12>0),", "&'Input Data'!AF12&" ("&'Input Data'!C12&")","")&IF(('Input Data'!AD13>TODAY())*(YEAR('Input Data'!AD13)>=2031)*('Input Data'!AE13>0),", "&'Input Data'!AF13&" ("&'Input Data'!C13&")","")&IF(('Input Data'!AD14>TODAY())*(YEAR('Input Data'!AD14)>=2031)*('Input Data'!AE14>0),", "&'Input Data'!AF14&" ("&'Input Data'!C14&")","")&IF(('Input Data'!AD15>TODAY())*(YEAR('Input Data'!AD15)>=2031)*('Input Data'!AE15>0),", "&'Input Data'!AF15&" ("&'Input Data'!C15&")","")&IF(('Input Data'!AD16>TODAY())*(YEAR('Input Data'!AD16)>=2031)*('Input Data'!AE16>0),", "&'Input Data'!AF16&" ("&'Input Data'!C16&")","")&IF(('Input Data'!AD17>TODAY())*(YEAR('Input Data'!AD17)>=2031)*('Input Data'!AE17>0),", "&'Input Data'!AF17&" ("&'Input Data'!C17&")","")&IF(('Input Data'!AD18>TODAY())*(YEAR('Input Data'!AD18)>=2031)*('Input Data'!AE18>0),", "&'Input Data'!AF18&" ("&'Input Data'!C18&")","")&IF(('Input Data'!AD19>TODAY())*(YEAR('Input Data'!AD19)>=2031)*('Input Data'!AE19>0),", "&'Input Data'!AF19&" ("&'Input Data'!C19&")","")&IF(('Input Data'!AD20>TODAY())*(YEAR('Input Data'!AD20)>=2031)*('Input Data'!AE20>0),", "&'Input Data'!AF20&" ("&'Input Data'!C20&")","")&IF(('Input Data'!AD21>TODAY())*(YEAR('Input Data'!AD21)>=2031)*('Input Data'!AE21>0),", "&'Input Data'!AF21&" ("&'Input Data'!C21&")","")&IF(('Input Data'!AD22>TODAY())*(YEAR('Input Data'!AD22)>=2031)*('Input Data'!AE22>0),", "&'Input Data'!AF22&" ("&'Input Data'!C22&")","")&IF(('Input Data'!AD23>TODAY())*(YEAR('Input Data'!AD23)>=2031)*('Input Data'!AE23>0),", "&'Input Data'!AF23&" ("&'Input Data'!C23&")","")&IF(('Input Data'!AD24>TODAY())*(YEAR('Input Data'!AD24)>=2031)*('Input Data'!AE24>0),", "&'Input Data'!AF24&" ("&'Input Data'!C24&")",""),3,999),"—") -> Fitness First (L3) (3.02), Fitness First (L4) (4.01), Fitness First N. Sydney (5.01), Elekta (6.04), Caldas Constructions (6.01), Luxasia (11.01), Haskoning Australia (11.02)
B25: TOTAL | D25: =SUMPRODUCT(('Input Data'!AD3:AD24>TODAY())*('Input Data'!AE3:AE24>0)*'Input Data'!AE3:AE24*'Input Data'!F3:F24) -> 7981402 | F25: 1 | G25: =SUMPRODUCT(('Input Data'!AD3:AD24>TODAY())*('Input Data'!AE3:AE24>0)*'Input Data'!F3:F24) -> 7788.4 | H25: 1
B27: PASSING RENT vs MARKET RENT — By Suite
B28: Suite | C28: Tenant | E28: NLA | F28: Face PSM | G28: Market PSM | H28: Var ($) | I28: Var (%) | J28: Position
B29: ='Input Data'!C3 -> 3.01 | C29: ='Input Data'!D3 -> Sydney Smiletree Pty Ltd | E29: ='Input Data'!F3 -> 107.7 | F29: ='Input Data'!J3 -> 1395.94 | G29: ='Input Data'!X3 -> 950 | H29: ='Input Data'!Y3 -> 445.94 | I29: ='Input Data'!Z3 -> 0.46941053 | J29: =IF('Input Data'!Y3>0,"▲ Above Mkt",IF('Input Data'!Y3<0,"▼ Below Mkt","≈ At Market")) -> ▲ Above Mkt
B30: ='Input Data'!C4 -> 3.02 | C30: ='Input Data'!D4 -> Fitness First Australia Pty Limited | E30: ='Input Data'!F4 -> 795.5 | F30: ='Input Data'!J4 -> 855.7 | G30: ='Input Data'!X4 -> 870 | H30: ='Input Data'!Y4 -> -14.3 | I30: ='Input Data'!Z4 -> -0.016436782 | J30: =IF('Input Data'!Y4>0,"▲ Above Mkt",IF('Input Data'!Y4<0,"▼ Below Mkt","≈ At Market")) -> ▼ Below Mkt
B31: ='Input Data'!C5 -> 4.01 | C31: ='Input Data'!D5 -> Fitness First Australia Pty Limited | E31: ='Input Data'!F5 -> 1047 | F31: ='Input Data'!J5 -> 855.7 | G31: ='Input Data'!X5 -> 870 | H31: ='Input Data'!Y5 -> -14.3 | I31: ='Input Data'!Z5 -> -0.016436782 | J31: =IF('Input Data'!Y5>0,"▲ Above Mkt",IF('Input Data'!Y5<0,"▼ Below Mkt","≈ At Market")) -> ▼ Below Mkt
B32: ='Input Data'!C6 -> 5.01 | C32: ='Input Data'!D6 -> Fitness First Australia Pty Limited | E32: ='Input Data'!F6 -> 437.1 | F32: ='Input Data'!J6 -> 855.7 | G32: ='Input Data'!X6 -> 870 | H32: ='Input Data'!Y6 -> -14.3 | I32: ='Input Data'!Z6 -> -0.016436782 | J32: =IF('Input Data'!Y6>0,"▲ Above Mkt",IF('Input Data'!Y6<0,"▼ Below Mkt","≈ At Market")) -> ▼ Below Mkt
B33: ='Input Data'!C7 -> 5.03 | C33: ='Input Data'!D7 -> Asterx Pty Ltd | E33: ='Input Data'!F7 -> 229.8 | F33: ='Input Data'!J7 -> 985.53 | G33: ='Input Data'!X7 -> 950 | H33: ='Input Data'!Y7 -> 35.53 | I33: ='Input Data'!Z7 -> 0.0374 | J33: =IF('Input Data'!Y7>0,"▲ Above Mkt",IF('Input Data'!Y7<0,"▼ Below Mkt","≈ At Market")) -> ▲ Above Mkt
B34: ='Input Data'!C8 -> 5.04 | C34: ='Input Data'!D8 -> Auctionsplus Pty Ltd | E34: ='Input Data'!F8 -> 413.5 | F34: ='Input Data'!J8 -> 1005.89 | G34: ='Input Data'!X8 -> 990 | H34: ='Input Data'!Y8 -> 15.89 | I34: ='Input Data'!Z8 -> 0.016050505 | J34: =IF('Input Data'!Y8>0,"▲ Above Mkt",IF('Input Data'!Y8<0,"▼ Below Mkt","≈ At Market")) -> ▲ Above Mkt
B35: ='Input Data'!C9 -> 6.02 | C35: ='Input Data'!D9 -> Sungrow Australia Group | E35: ='Input Data'!F9 -> 451.7 | F35: ='Input Data'!J9 -> 954.5 | G35: ='Input Data'!X9 -> 955 | H35: ='Input Data'!Y9 -> -0.5 | I35: ='Input Data'!Z9 -> -0.00052356021 | J35: =IF('Input Data'!Y9>0,"▲ Above Mkt",IF('Input Data'!Y9<0,"▼ Below Mkt","≈ At Market")) -> ▼ Below Mkt
B36: ='Input Data'!C10 -> 6.03 | C36: ='Input Data'!D10 -> Keeping Company Pty Ltd | E36: ='Input Data'!F10 -> 189.4 | F36: ='Input Data'!J10 -> 1055.72 | G36: ='Input Data'!X10 -> 990 | H36: ='Input Data'!Y10 -> 65.72 | I36: ='Input Data'!Z10 -> 0.066383838 | J36: =IF('Input Data'!Y10>0,"▲ Above Mkt",IF('Input Data'!Y10<0,"▼ Below Mkt","≈ At Market")) -> ▲ Above Mkt
B37: ='Input Data'!C11 -> 6.04 | C37: ='Input Data'!D11 -> Elekta Pty Limited | E37: ='Input Data'!F11 -> 267.9 | F37: ='Input Data'!J11 -> 954.5 | G37: ='Input Data'!X11 -> 955 | H37: ='Input Data'!Y11 -> -0.5 | I37: ='Input Data'!Z11 -> -0.00052356021 | J37: =IF('Input Data'!Y11>0,"▲ Above Mkt",IF('Input Data'!Y11<0,"▼ Below Mkt","≈ At Market")) -> ▼ Below Mkt
B38: ='Input Data'!C12 -> 7.01 | C38: ='Input Data'!D12 -> Sungrow Australia Group | E38: ='Input Data'!F12 -> 484.1 | F38: ='Input Data'!J12 -> 1911.44 | G38: ='Input Data'!X12 -> 1020 | H38: ='Input Data'!Y12 -> 891.44 | I38: ='Input Data'!Z12 -> 0.87396078 | J38: =IF('Input Data'!Y12>0,"▲ Above Mkt",IF('Input Data'!Y12<0,"▼ Below Mkt","≈ At Market")) -> ▲ Above Mkt
B39: ='Input Data'!C14 -> 8.01 | C39: ='Input Data'!D14 -> Vanderlande Industries Australia Pty Ltd | E39: ='Input Data'!F14 -> 686.7 | F39: ='Input Data'!J14 -> 1029.25 | G39: ='Input Data'!X14 -> 990 | H39: ='Input Data'!Y14 -> 39.25 | I39: ='Input Data'!Z14 -> 0.039646465 | J39: =IF('Input Data'!Y14>0,"▲ Above Mkt",IF('Input Data'!Y14<0,"▼ Below Mkt","≈ At Market")) -> ▲ Above Mkt
B40: ='Input Data'!C15 -> 8.03 | C40: ='Input Data'!D15 -> Can Too Foundation Limited | E40: ='Input Data'!F15 -> 116.3 | F40: ='Input Data'!J15 -> 1027.12 | G40: ='Input Data'!X15 -> 990 | H40: ='Input Data'!Y15 -> 37.12 | I40: ='Input Data'!Z15 -> 0.037494949 | J40: =IF('Input Data'!Y15>0,"▲ Above Mkt",IF('Input Data'!Y15<0,"▼ Below Mkt","≈ At Market")) -> ▲ Above Mkt
B41: ='Input Data'!C16 -> 9.01 | C41: ='Input Data'!D16 -> Pitt & Sherry (Operations) Pty Ltd | E41: ='Input Data'!F16 -> 453.3 | F41: ='Input Data'!J16 -> 1065.96 | G41: ='Input Data'!X16 -> 1040 | H41: ='Input Data'!Y16 -> 25.96 | I41: ='Input Data'!Z16 -> 0.024961538 | J41: =IF('Input Data'!Y16>0,"▲ Above Mkt",IF('Input Data'!Y16<0,"▼ Below Mkt","≈ At Market")) -> ▲ Above Mkt
B42: ='Input Data'!C17 -> 12.01 | C42: ='Input Data'!D17 -> Hulsbosch Design Pty Ltd | E42: ='Input Data'!F17 -> 251 | F42: ='Input Data'!J17 -> 985 | G42: ='Input Data'!X17 -> 1040 | H42: ='Input Data'!Y17 -> -55 | I42: ='Input Data'!Z17 -> -0.052884615 | J42: =IF('Input Data'!Y17>0,"▲ Above Mkt",IF('Input Data'!Y17<0,"▼ Below Mkt","≈ At Market")) -> ▼ Below Mkt
B43: ='Input Data'!C18 -> 9.02 | C43: ='Input Data'!D18 -> Smile Partners Australia | E43: ='Input Data'!F18 -> 344.5 | F43: ='Input Data'!J18 -> 990.29 | G43: ='Input Data'!X18 -> 990 | H43: ='Input Data'!Y18 -> 0.29 | I43: ='Input Data'!Z18 -> 0.00029292929 | J43: =IF('Input Data'!Y18>0,"▲ Above Mkt",IF('Input Data'!Y18<0,"▼ Below Mkt","≈ At Market")) -> ▲ Above Mkt
B44: ='Input Data'!C19 -> 12.02 | C44: ='Input Data'!D19 -> AEI Insurance Group Pty Ltd | E44: ='Input Data'!F19 -> 536 | F44: ='Input Data'!J19 -> 988 | G44: ='Input Data'!X19 -> 1010 | H44: ='Input Data'!Y19 -> -22 | I44: ='Input Data'!Z19 -> -0.021782178 | J44: =IF('Input Data'!Y19>0,"▲ Above Mkt",IF('Input Data'!Y19<0,"▼ Below Mkt","≈ At Market")) -> ▼ Below Mkt
B46: UPCOMING CRITICAL DATES — Next 18 Months
B47: Suite / Tenant | D47: Event | E47: Due Date | F47: Days Away | G47: Action Required
B48: 6.01/Caldas | D48: New Lease Commences | E48: 46204 | F48: =IFERROR(INT(E48-TODAY()),"") -> -107 | G48: Ensure fitout complete, BG received, rent commences
...

Sheet Valuations
A1: 1 ELIZABETH PLAZA, NORTH SYDNEY — VALUATIONS, LAND TAX & MORTGAGE REGISTER
A2: Yellow cells = input. All Dashboard valuation figures pull from this tab automatically. Update each time a new valuation or assessment is received.
B4: PROPERTY VALUATIONS
C5: Valuation 1 (Most Recent) | D5: Valuation 2 | E5: Valuation 3 | F5: Notes
B6: Valuation Amount
B7: Date of Valuation
B8: Valuer / Firm
B9: Valuation Basis
B10: Capitalisation Rate (%)
B11: Passing Yield (%)
B12: Land Value ($)
B13: Improvement Value ($)
B14: VALUATION MOVEMENT
B15: Val 1 vs Val 2 ($) | C15: =IFERROR(C6-D6,"") -> 0 | E15: =IFERROR((C6-D6)/D6,"")
B16: Val 2 vs Val 3 ($) | C16: =IFERROR(D6-E6,"") -> 0 | E16: =IFERROR((D6-E6)/E6,"")
B18: LAND TAX ASSESSMENTS — NSW
C19: Assessment 1 (Most Recent) | D19: Assessment 2 | E19: Assessment 3 | F19: Notes
B20: Land Tax Year
B21: Assessed Land Value ($)
B22: Land Tax Payable ($)
B23: Assessment Date
B24: Threshold Applied ($)
B25: Tax Rate Applied (%)
B26: Payment Due Date
B27: Assessment Reference / Notice
B29: LAND VALUE MOVEMENT
B30: Assessment 1 vs 2 Land Value Change | C30: =IFERROR(C21-D21,"") -> 0 | E30: =IFERROR((C21-D21)/D21,"")
B31: Assessment 2 vs 3 Land Value Change | C31: =IFERROR(D21-E21,"") -> 0 | E31: =IFERROR((D21-E21)/E21,"")
B33: MORTGAGE / DEBT DETAILS — (Not displayed on Dashboard)
B34: Field | D34: Current | G34: Prior
B35: Lender / Bank
B36: Loan Amount ($)
B37: As at Date
B38: Interest Rate (%)
B39: Loan Type
B40: Facility Expiry / Review Date
B41: LVR (%) | D41: =IFERROR(D36/Valuations!C6,"")
B42: Interest Cover Ratio (ICR)
B43: Covenants / Notes
B45: LEGEND: Yellow = input | Teal = calculated | Valuation 1 = most recent | LVR auto-calculates from Loan Amount ÷ Latest Valuation

Sheet Market Rents 26-27
A1: 1 ELIZABETH PLAZA, NORTH SYDNEY — MARKET RENTS 2026-27 | Face Rent PSM ($) | Update annually or when market moves materially
A2: Source: Market assessment 2026 | Update annually or when market moves | Market PSM (col E) feeds Var to Mkt analysis in Input Data tab | Yellow = input cells
B3: Suite | C3: Size (sqm) | D3: Current Tenant | E3: Passing PSM ($) | F3: Market Rent PSM ($) | G3: Var ($) | H3: Var (%) | I3: New Tenant Incentive 3yr | J3: 4yr | K3: 5yr | L3: Renewal Incentive 3yr | M3: 5yr
B4: 3.01 | C4: =IFERROR(INDEX('Input Data'!F:F,MATCH(B4,'Input Data'!$C:$C,0)),"") -> 107.7 | D4: =IFERROR(INDEX('Input Data'!D:D,MATCH(B4,'Input Data'!$C:$C,0)),"") -> Sydney Smiletree Pty Ltd | E4: =IFERROR(INDEX('Input Data'!J:J,MATCH(B4,'Input Data'!$C:$C,0)),"") -> 1395.94 | F4: 950 | G4: =IFERROR(E4-F4,"") -> 445.94 | H4: =IFERROR((E4-F4)/F4,"") -> 0.46941053 | I4: 35-45% | J4: 38-45% | K4: 40-45% | L4: 28-32% | M4: 35-42%
B5: 3.02 | C5: =IFERROR(INDEX('Input Data'!F:F,MATCH(B5,'Input Data'!$C:$C,0)),"") -> 795.5 | D5: =IFERROR(INDEX('Input Data'!D:D,MATCH(B5,'Input Data'!$C:$C,0)),"") -> Fitness First Australia Pty Limited | E5: =IFERROR(INDEX('Input Data'!J:J,MATCH(B5,'Input Data'!$C:$C,0)),"") -> 855.7 | F5: 870 | G5: =IFERROR(E5-F5,"") -> -14.3 | H5: =IFERROR((E5-F5)/F5,"") -> -0.016436782 | I5: 35-45% | J5: 38-45% | K5: 40-45% | L5: 28-32% | M5: 35-42%
B6: 4.01 | C6: =IFERROR(INDEX('Input Data'!F:F,MATCH(B6,'Input Data'!$C:$C,0)),"") -> 1047 | D6: =IFERROR(INDEX('Input Data'!D:D,MATCH(B6,'Input Data'!$C:$C,0)),"") -> Fitness First Australia Pty Limited | E6: =IFERROR(INDEX('Input Data'!J:J,MATCH(B6,'Input Data'!$C:$C,0)),"") -> 855.7 | F6: 870 | G6: =IFERROR(E6-F6,"") -> -14.3 | H6: =IFERROR((E6-F6)/F6,"") -> -0.016436782 | I6: 35-45% | J6: 38-45% | K6: 40-45% | L6: 28-32% | M6: 35-42%
B7: 5.01 | C7: =IFERROR(INDEX('Input Data'!F:F,MATCH(B7,'Input Data'!$C:$C,0)),"") -> 437.1 | D7: =IFERROR(INDEX('Input Data'!D:D,MATCH(B7,'Input Data'!$C:$C,0)),"") -> Fitness First Australia Pty Limited | E7: =IFERROR(INDEX('Input Data'!J:J,MATCH(B7,'Input Data'!$C:$C,0)),"") -> 855.7 | F7: 870 | G7: =IFERROR(E7-F7,"") -> -14.3 | H7: =IFERROR((E7-F7)/F7,"") -> -0.016436782 | I7: 35-45% | J7: 38-45% | K7: 40-45% | L7: 28-32% | M7: 35-42%
B8: 5.03 | C8: =IFERROR(INDEX('Input Data'!F:F,MATCH(B8,'Input Data'!$C:$C,0)),"") -> 229.8 | D8: =IFERROR(INDEX('Input Data'!D:D,MATCH(B8,'Input Data'!$C:$C,0)),"") -> Asterx Pty Ltd | E8: =IFERROR(INDEX('Input Data'!J:J,MATCH(B8,'Input Data'!$C:$C,0)),"") -> 985.53 | F8: 1005 | G8: =IFERROR(E8-F8,"") -> -19.47 | H8: =IFERROR((E8-F8)/F8,"") -> -0.019373134 | I8: 35-45% | J8: 38-45% | K8: 40-45% | L8: 28-32% | M8: 35-42%
B9: 5.04 | C9: =IFERROR(INDEX('Input Data'!F:F,MATCH(B9,'Input Data'!$C:$C,0)),"") -> 413.5 | D9: =IFERROR(INDEX('Input Data'!D:D,MATCH(B9,'Input Data'!$C:$C,0)),"") -> Auctionsplus Pty Ltd | E9: =IFERROR(INDEX('Input Data'!J:J,MATCH(B9,'Input Data'!$C:$C,0)),"") -> 1005.89 | F9: 1000 | G9: =IFERROR(E9-F9,"") -> 5.89 | H9: =IFERROR((E9-F9)/F9,"") -> 0.00589 | I9: 35-45% | J9: 38-45% | K9: 40-45% | L9: 28-32% | M9: 35-42%
B10: 6.01 | C10: =IFERROR(INDEX('Input Data'!F:F,MATCH(B10,'Input Data'!$C:$C,0)),"") -> 186.4 | D10: =IFERROR(INDEX('Input Data'!D:D,MATCH(B10,'Input Data'!$C:$C,0)),"") -> Caldas Constructions Pty Ltd | E10: =IFERROR(INDEX('Input Data'!J:J,MATCH(B10,'Input Data'!$C:$C,0)),"") -> 920 | F10: 1010 | G10: =IFERROR(E10-F10,"") -> -90 | H10: =IFERROR((E10-F10)/F10,"") -> -0.089108911 | I10: 35-45% | J10: 38-45% | K10: 40-45% | L10: 28-32% | M10: 35-42%
B11: 6.02 | C11: =IFERROR(INDEX('Input Data'!F:F,MATCH(B11,'Input Data'!$C:$C,0)),"") -> 451.7 | D11: =IFERROR(INDEX('Input Data'!D:D,MATCH(B11,'Input Data'!$C:$C,0)),"") -> Sungrow Australia Group | E11: =IFERROR(INDEX('Input Data'!J:J,MATCH(B11,'Input Data'!$C:$C,0)),"") -> 954.5 | F11: 1005 | G11: =IFERROR(E11-F11,"") -> -50.5 | H11: =IFERROR((E11-F11)/F11,"") -> -0.050248756 | I11: 35-45% | J11: 38-45% | K11: 40-45% | L11: 28-32% | M11: 35-42%
B12: 6.03 | C12: =IFERROR(INDEX('Input Data'!F:F,MATCH(B12,'Input Data'!$C:$C,0)),"") -> 189.4 | D12: =IFERROR(INDEX('Input Data'!D:D,MATCH(B12,'Input Data'!$C:$C,0)),"") -> Keeping Company Pty Ltd | E12: =IFERROR(INDEX('Input Data'!J:J,MATCH(B12,'Input Data'!$C:$C,0)),"") -> 1055.72 | F12: 1010 | G12: =IFERROR(E12-F12,"") -> 45.72 | H12: =IFERROR((E12-F12)/F12,"") -> 0.045267327 | I12: 35-45% | J12: 38-45% | K12: 40-45% | L12: 28-32% | M12: 35-42%
B13: 6.04 | C13: =IFERROR(INDEX('Input Data'!F:F,MATCH(B13,'Input Data'!$C:$C,0)),"") -> 267.9 | D13: =IFERROR(INDEX('Input Data'!D:D,MATCH(B13,'Input Data'!$C:$C,0)),"") -> Elekta Pty Limited | E13: =IFERROR(INDEX('Input Data'!J:J,MATCH(B13,'Input Data'!$C:$C,0)),"") -> 954.5 | F13: 1005 | G13: =IFERROR(E13-F13,"") -> -50.5 | H13: =IFERROR((E13-F13)/F13,"") -> -0.050248756 | I13: 35-45% | J13: 38-45% | K13: 40-45% | L13: 28-32% | M13: 35-42%
B14: 7.01 | C14: =IFERROR(INDEX('Input Data'!F:F,MATCH(B14,'Input Data'!$C:$C,0)),"") -> 484.1 | D14: =IFERROR(INDEX('Input Data'!D:D,MATCH(B14,'Input Data'!$C:$C,0)),"") -> Sungrow Australia Group | E14: =IFERROR(INDEX('Input Data'!J:J,MATCH(B14,'Input Data'!$C:$C,0)),"") -> 1911.44 | F14: 1015 | G14: =IFERROR(E14-F14,"") -> 896.44 | H14: =IFERROR((E14-F14)/F14,"") -> 0.88319212 | I14: 35-45% | J14: 38-45% | K14: 40-45% | L14: 28-32% | M14: 35-42%
B15: 7.02 | C15: =IFERROR(INDEX('Input Data'!F:F,MATCH(B15,'Input Data'!$C:$C,0)),"") -> 365.5 | D15: =IFERROR(INDEX('Input Data'!D:D,MATCH(B15,'Input Data'!$C:$C,0)),"") -> Sungrow Australia Group | E15: =IFERROR(INDEX('Input Data'!J:J,MATCH(B15,'Input Data'!$C:$C,0)),"") -> 0 | F15: 1015 | G15: =IFERROR(E15-F15,"") -> -1015 | H15: =IFERROR((E15-F15)/F15,"") -> -1 | I15: 35-45% | J15: 38-45% | K15: 40-45% | L15: 28-32% | M15: 35-42%
... B19: 9.02 | C19: =IFERROR(INDEX('Input Data'!F:F,MATCH(B19,'Input Data'!$C:$C,0)),"") -> 344.5 | D19: =IFERROR(INDEX('Input Data'!D:D,MATCH(B19,'Input Data'!$C:$C,0)),"") -> Smile Partners Australia | E19: =IFERROR(INDEX('Input Data'!J:J,MATCH(B19,'Input Data'!$C:$C,0)),"") -> 990.29 | F19: 1030 | G19: =IFERROR(E19-F19,"") -> -39.71 | H19: =IFERROR((E19-F19)/F19,"") -> -0.038553398 | I19: 35-45% | J19: 38-45% | K19: 40-45% | L19: 28-32% | M19: 35-42%
B20: 10.01 | C20: =IFERROR(INDEX('Input Data'!F:F,MATCH(B20,'Input Data'!$C:$C,0)),"") | D20: =IFERROR(INDEX('Input Data'!D:D,MATCH(B20,'Input Data'!$C:$C,0)),"") | E20: =IFERROR(INDEX('Input Data'!J:J,MATCH(B20,'Input Data'!$C:$C,0)),"") | F20: 1040 | G20: =IFERROR(E20-F20,"") | H20: =IFERROR((E20-F20)/F20,"") | I20: 35-45% | J20: 38-45% | K20: 40-45% | L20: 28-32% | M20: 35-42%
B21: 10.02 | C21: =IFERROR(INDEX('Input Data'!F:F,MATCH(B21,'Input Data'!$C:$C,0)),"") | D21: =IFERROR(INDEX('Input Data'!D:D,MATCH(B21,'Input Data'!$C:$C,0)),"") | E21: =IFERROR(INDEX('Input Data'!J:J,MATCH(B21,'Input Data'!$C:$C,0)),"") | F21: 1040 | G21: =IFERROR(E21-F21,"") | H21: =IFERROR((E21-F21)/F21,"") | I21: 35-45% | J21: 38-45% | K21: 40-45% | L21: 28-32% | M21: 35-42%
B22: 11.01 | C22: =IFERROR(INDEX('Input Data'!F:F,MATCH(B22,'Input Data'!$C:$C,0)),"") | D22: =IFERROR(INDEX('Input Data'!D:D,MATCH(B22,'Input Data'!$C:$C,0)),"") | E22: =IFERROR(INDEX('Input Data'!J:J,MATCH(B22,'Input Data'!$C:$C,0)),"") | F22: 1045 | G22: =IFERROR(E22-F22,"") | H22: =IFERROR((E22-F22)/F22,"") | I22: 35-45% | J22: 38-45% | K22: 40-45% | L22: 28-32% | M22: 35-42%
